File: SP-M4-239-3-0104-#4/Irradiated/MH27K.dc.dat
[Header]
TITLE,MPMS DC Measurement
BYAPP,MPMS Measurement,2.1,Summary
FILEOPENTIME, 1467254259.689000 6/29/2016, 9:37:39 PM

INFO, APPNAME, MPMS MultiVu Application, Revision 1.60,  Build 081

INFO, NAME, tb11c
INFO, WEIGHT, 0.100
INFO, AREA, 1.000
INFO, LENGTH, 1.000
INFO, SHAPE, 1
INFO, COMMENT, 650C in 0.1% O2 in AR, single xtal, H//ab, lN2 quench
INFO, SEQUENCE FILE: Sequence_MT_5_27_77_45.seq


INFO, BACKGROUND DATA FILE:, None


STARTUPAXIS,X,4,LINEAR,AUTO,0.000000,0.000000
STARTUPAXIS,Y1,5,LINEAR,AUTO,0.000000,0.000000


STARTUPGROUP,Longitudinal
FIELDGROUP,Longitudinal,1,2,3,4,5,6,7,8,9,15,16,17,18,27,28
FIELDGROUP,Transverse,1,2,3,4,10,11,12,13,14,19,20,21,22,27,28

PLOT_APPEARANCE,ALL,HORZ_GRID_ON,VERT_GRID_ON,MARKERS_AND_LINES

[Data]
Time,Comment,Field (Oe),Temperature (K),Long Moment (emu),Long Scan Std Dev,Long Algorithm,Long Reg Fit,Long Percent Error (%),Trans Moment (emu),Trans Scan Std Dev,Trans Algorithm,Trans Reg Fit,Trans Percent Error (%),Long Moment [w/o ABS] (emu),Long Scan Std Dev [w/o ABS],Long Reg Fit [w/o ABS],Long Percent Error [w/o ABS] (%),Trans Moment [w/o ABS] (emu),Trans Scan Std Dev [w/o ABS],Trans Reg Fit [w/o ABS],Trans Percent Error [w/o ABS] (%),Points per Scan,Scans per Measurement,Scan Length (cm),Delta Temp (K),Rot Position (deg),Error,EC Comp. Running,Using ABS,
1467254259.689,,1.000000e+003,2.699922e+001,-5.670004e-002,9.020742e-005,3,9.982792e-001,1.590959e-001,,,,,,,,,,,,,,64,2,3.000000e+000,1.491547e-003,0.000000e+000,0,,0,
1467254312.230,,2.008724e+003,2.699847e+001,-6.616414e-002,1.364109e-003,3,9.978874e-001,2.061705e+000,,,,,,,,,,,,,,64,2,3.000000e+000,3.000259e-003,0.000000e+000,0,,0,
1467254366.330,,3.012974e+003,2.700072e+001,-6.218494e-002,1.728237e-003,3,9.979115e-001,2.779189e+000,,,,,,,,,,,,,,64,2,3.000000e+000,3.751755e-003,0.000000e+000,0,,0,
1467254419.121,,4.017150e+003,2.700109e+001,-5.857164e-002,1.601132e-003,3,9.973922e-001,2.733631e+000,,,,,,,,,,,,,,64,2,3.000000e+000,2.248764e-003,0.000000e+000,0,,0,
1467254472.231,,5.021401e+003,2.699735e+001,-5.551531e-002,1.516931e-003,3,9.972974e-001,2.732455e+000,,,,,,,,,,,,,,64,2,3.000000e+000,5.239487e-003,0.000000e+000,0,,0,
1467254525.852,,6.025207e+003,2.699903e+001,-5.286924e-002,1.444620e-003,3,9.972475e-001,2.732440e+000,,,,,,,,,,,,,,64,2,3.000000e+000,3.000259e-003,0.000000e+000,0,,0,
1467254578.423,,7.029161e+003,2.699922e+001,-5.061673e-002,1.380085e-003,3,9.973696e-001,2.726540e+000,,,,,,,,,,,,,,64,2,3.000000e+000,4.499435e-003,0.000000e+000,0,,0,
1467254675.423,,8.041567e+003,2.699922e+001,-4.834676e-002,1.285748e-003,3,9.971060e-001,2.659428e+000,,,,,,,,,,,,,,64,2,3.000000e+000,4.499435e-003,0.000000e+000,0,,0,
1467254729.584,,9.044037e+003,2.699866e+001,-4.639008e-002,1.181626e-003,3,9.972981e-001,2.547153e+000,,,,,,,,,,,,,,64,2,3.000000e+000,2.250671e-003,0.000000e+000,0,,0,
1467254782.265,,1.004843e+004,2.699959e+001,-4.471667e-002,1.193991e-003,3,9.971578e-001,2.670125e+000,,,,,,,,,,,,,,64,2,3.000000e+000,2.241135e-003,0.000000e+000,0,,0,
1467254893.928,,1.506954e+004,2.700090e+001,-3.749879e-002,1.332694e-003,3,9.937278e-001,3.553965e+000,,,,,,,,,,,,,,64,2,3.000000e+000,3.000259e-003,0.000000e+000,0,,0,
1467254965.108,,2.009094e+004,2.699903e+001,-3.172860e-002,1.194061e-003,3,9.923918e-001,3.763359e+000,,,,,,,,,,,,,,64,2,3.000000e+000,3.000259e-003,0.000000e+000,0,,0,
1467255078.630,,2.510997e+004,2.699903e+001,-2.508583e-002,3.011919e-004,3,9.937107e-001,1.200645e+000,,,,,,,,,,,,,,64,2,3.000000e+000,0.000000e+000,0.000000e+000,0,,0,
1467255149.190,,3.012900e+004,2.699978e+001,-2.221916e-002,9.646926e-004,3,9.894350e-001,4.341714e+000,,,,,,,,,,,,,,64,2,3.000000e+000,0.000000e+000,0.000000e+000,0,,0,
1467255220.221,,3.515174e+004,2.699997e+001,-1.836750e-002,9.101388e-004,3,9.807944e-001,4.955158e+000,,,,,,,,,,,,,,64,2,3.000000e+000,1.501083e-003,0.000000e+000,0,,0,
1467255334.882,,4.017299e+004,2.699997e+001,-1.083915e-002,1.826425e-003,3,9.865572e-001,1.685026e+001,,,,,,,,,,,,,,64,2,3.000000e+000,7.495880e-004,0.000000e+000,0,,0,
1467255405.983,,4.519053e+004,2.700035e+001,-1.207318e-002,9.644220e-004,3,9.676755e-001,7.988135e+000,,,,,,,,,,,,,,64,2,3.000000e+000,6.740570e-003,0.000000e+000,0,,0,
1467255478.694,,5.021252e+004,2.700053e+001,-8.894695e-003,7.025491e-004,3,9.678881e-001,7.898519e+000,,,,,,,,,,,,,,64,2,3.000000e+000,2.250671e-003,0.000000e+000,0,,0,
1467255591.055,,5.523453e+004,2.700034e+001,-5.751051e-003,1.232940e-004,3,9.431497e-001,2.143852e+000,,,,,,,,,,,,,,64,2,3.000000e+000,3.740311e-003,0.000000e+000,0,,0,
1467255663.135,,6.025504e+004,2.700053e+001,-3.858232e-003,8.691311e-004,3,8.823782e-001,2.252666e+001,,,,,,,,,,,,,,64,2,3.000000e+000,1.499176e-003,0.000000e+000,0,,0,
1467255775.547,,6.527852e+004,2.699997e+001,-1.269659e-003,1.883742e-005,3,7.142999e-001,1.483659e+000,,,,,,,,,,,,,,64,2,3.000000e+000,2.250671e-003,0.000000e+000,0,,0,
1467255845.377,,7.029605e+004,2.700034e+001,6.144943e-004,2.165309e-004,3,3.700491e-001,3.523725e+001,,,,,,,,,,,,,,64,2,3.000000e+000,3.751755e-003,0.000000e+000,0,,0,
1467255979.291,,6.527111e+004,2.700016e+001,3.833959e-002,1.382627e-004,3,9.918654e-001,3.606265e-001,,,,,,,,,,,,,,64,2,3.000000e+000,3.740311e-003,0.000000e+000,0,,0,
1467256053.411,,6.025207e+004,2.700016e+001,3.930813e-002,8.091352e-004,3,9.911858e-001,2.058443e+000,,,,,,,,,,,,,,64,2,3.000000e+000,3.740311e-003,0.000000e+000,0,,0,
1467256127.302,,5.523750e+004,2.699828e+001,3.919757e-002,1.751755e-004,3,9.926287e-001,4.469039e-001,,,,,,,,,,,,,,64,2,3.000000e+000,3.000259e-003,0.000000e+000,0,,0,
1467256201.413,,5.021105e+004,2.700053e+001,4.023427e-002,6.422653e-004,3,9.929292e-001,1.596314e+000,,,,,,,,,,,,,,64,2,3.000000e+000,3.740311e-003,0.000000e+000,0,,0,
1467256272.973,,4.518905e+004,2.699847e+001,4.095286e-002,6.730140e-004,3,9.937800e-001,1.643387e+000,,,,,,,,,,,,,,64,2,3.000000e+000,2.250671e-003,0.000000e+000,0,,0,
1467256345.634,,4.017077e+004,2.699959e+001,4.174289e-002,6.496568e-004,3,9.944690e-001,1.556329e+000,,,,,,,,,,,,,,64,2,3.000000e+000,7.514954e-004,0.000000e+000,0,,0,
1467256418.015,,3.515026e+004,2.699959e+001,4.277506e-002,7.433887e-004,3,9.947051e-001,1.737902e+000,,,,,,,,,,,,,,64,2,3.000000e+000,2.241135e-003,0.000000e+000,0,,0,
1467256511.266,,3.012752e+004,2.699997e+001,4.319999e-002,6.074678e-004,3,9.942090e-001,1.406176e+000,,,,,,,,,,,,,,64,2,3.000000e+000,5.250931e-003,0.000000e+000,0,,0,
1467256583.167,,2.510849e+004,2.699884e+001,4.523473e-002,8.045991e-004,3,9.955609e-001,1.778720e+000,,,,,,,,,,,,,,64,2,3.000000e+000,3.000259e-003,0.000000e+000,0,,0,
1467256655.547,,2.008798e+004,2.700147e+001,4.710984e-002,8.614421e-004,3,9.962361e-001,1.828582e+000,,,,,,,,,,,,,,64,2,3.000000e+000,5.990982e-003,0.000000e+000,0,,0,
1467256727.598,,1.506687e+004,2.700034e+001,4.958296e-002,9.739531e-004,3,9.964494e-001,1.964290e+000,,,,,,,,,,,,,,64,2,3.000000e+000,7.495880e-004,0.000000e+000,0,,0,
1467256840.261,,1.004903e+004,2.699865e+001,5.297454e-002,1.100164e-003,3,9.966177e-001,2.076780e+000,,,,,,,,,,,,,,64,2,3.000000e+000,4.499435e-003,0.000000e+000,0,,0,
1467256898.262,,8.040825e+003,2.699940e+001,5.516469e-002,1.400511e-003,3,9.969428e-001,2.538781e+000,,,,,,,,,,,,,,64,2,3.000000e+000,3.749847e-003,0.000000e+000,0,,0,
1467257000.253,,6.025800e+003,2.699922e+001,5.798124e-002,1.510261e-003,3,9.968547e-001,2.604741e+000,,,,,,,,,,,,,,64,2,3.000000e+000,7.514954e-004,0.000000e+000,0,,0,
1467257058.513,,4.017595e+003,2.699885e+001,6.150535e-002,1.482012e-003,3,9.969007e-001,2.409566e+000,,,,,,,,,,,,,,64,2,3.000000e+000,1.491547e-003,0.000000e+000,0,,0,
1467257116.414,,2.009317e+003,2.700035e+001,6.779455e-002,1.626415e-003,3,9.971284e-001,2.399036e+000,,,,,,,,,,,,,,64,2,3.000000e+000,3.740311e-003,0.000000e+000,0,,0,
1467257174.654,,4.892998e-001,2.699884e+001,7.378706e-002,1.505396e-003,3,9.972317e-001,2.040190e+000,,,,,,,,,,,,,,64,2,3.000000e+000,3.000259e-003,0.000000e+000,0,,0,
1467257240.735,,-2.009391e+003,2.699978e+001,6.677793e-002,1.634391e-003,3,9.970924e-001,2.447502e+000,,,,,,,,,,,,,,64,2,3.000000e+000,0.000000e+000,0.000000e+000,0,,0,
1467257299.566,,-4.017595e+003,2.699978e+001,5.845206e-002,1.479420e-003,3,9.969434e-001,2.530998e+000,,,,,,,,,,,,,,64,2,3.000000e+000,1.501083e-003,0.000000e+000,0,,0,
1467257357.486,,-6.025800e+003,2.699997e+001,5.276380e-002,1.393773e-003,3,9.969017e-001,2.641532e+000,,,,,,,,,,,,,,64,2,3.000000e+000,2.250671e-003,0.000000e+000,0,,0,
1467257457.827,,-8.040083e+003,2.699959e+001,4.832779e-002,1.243403e-003,3,9.966292e-001,2.572854e+000,,,,,,,,,,,,,,64,2,3.000000e+000,7.514954e-004,0.000000e+000,0,,0,
1467257515.418,,-1.004755e+004,2.700053e+001,4.459301e-002,1.025583e-003,3,9.967174e-001,2.299874e+000,,,,,,,,,,,,,,64,2,3.000000e+000,1.499176e-003,0.000000e+000,0,,0,
1467257626.861,,-1.507073e+004,2.699922e+001,3.749765e-002,1.265491e-003,3,9.934715e-001,3.374853e+000,,,,,,,,,,,,,,64,2,3.000000e+000,2.241135e-003,0.000000e+000,0,,0,
1467257698.922,,-2.009095e+004,2.699903e+001,3.165795e-002,1.123872e-003,3,9.918952e-001,3.550047e+000,,,,,,,,,,,,,,64,2,3.000000e+000,3.000259e-003,0.000000e+000,0,,0,
1467257770.082,,-2.511145e+004,2.700034e+001,2.663689e-002,9.440328e-004,3,9.911072e-001,3.544081e+000,,,,,,,,,,,,,,64,2,3.000000e+000,2.250671e-003,0.000000e+000,0,,0,
1467257841.773,,-3.013122e+004,2.699903e+001,2.231972e-002,9.040249e-004,3,9.886267e-001,4.050342e+000,,,,,,,,,,,,,,64,2,3.000000e+000,1.491547e-003,0.000000e+000,0,,0,
1467257915.044,,-3.515396e+004,2.699735e+001,1.852131e-002,7.175080e-004,3,9.781345e-001,3.873959e+000,,,,,,,,,,,,,,64,2,3.000000e+000,5.239487e-003,0.000000e+000,0,,0,
1467257986.075,,-4.017446e+004,2.699978e+001,1.489174e-002,7.141006e-004,3,9.808187e-001,4.795280e+000,,,,,,,,,,,,,,64,2,3.000000e+000,1.501083e-003,0.000000e+000,0,,0,
1467258098.846,,-4.519498e+004,2.699940e+001,1.059834e-002,2.526736e-004,3,9.765411e-001,2.384088e+000,,,,,,,,,,,,,,64,2,3.000000e+000,4.499435e-003,0.000000e+000,0,,0,
1467258170.006,,-5.021698e+004,2.700072e+001,8.854421e-003,6.787256e-004,3,9.683465e-001,7.665387e+000,,,,,,,,,,,,,,64,2,3.000000e+000,2.250671e-003,0.000000e+000,0,,0,
1467258282.958,,-5.523601e+004,2.699959e+001,5.225035e-003,2.385363e-004,3,9.484060e-001,4.565258e+000,,,,,,,,,,,,,,64,2,3.000000e+000,1.501083e-003,0.000000e+000,0,,0,
1467258353.288,,-6.025800e+004,2.699941e+001,3.891507e-003,5.255923e-004,3,9.145402e-001,1.350614e+001,,,,,,,,,,,,,,64,2,3.000000e+000,6.750107e-003,0.000000e+000,0,,0,
1467258530.200,,-6.527852e+004,2.700072e+001,-1.090331e-004,5.998304e-005,3,0.000000e+000,5.501361e+001,,,,,,,,,,,,,,64,2,3.000000e+000,3.751755e-003,0.000000e+000,0,,0,
1467258706.102,,-7.030051e+004,2.700147e+001,-6.198876e-003,1.319697e-003,3,9.324114e-001,2.128929e+001,,,,,,,,,,,,,,64,2,3.000000e+000,3.000259e-003,0.000000e+000,0,,0,
1467258842.835,,-6.527258e+004,2.699997e+001,-3.481505e-002,2.940665e-004,3,9.891869e-001,8.446533e-001,,,,,,,,,,,,,,64,2,3.000000e+000,1.501083e-003,0.000000e+000,0,,0,
1467258916.896,,-6.024614e+004,2.699997e+001,-3.900342e-002,6.559314e-004,3,9.917529e-001,1.681728e+000,,,,,,,,,,,,,,64,2,3.000000e+000,2.250671e-003,0.000000e+000,0,,0,
1467258990.057,,-5.522859e+004,2.699997e+001,-3.949862e-002,5.508646e-004,3,9.926338e-001,1.394643e+000,,,,,,,,,,,,,,64,2,3.000000e+000,1.501083e-003,0.000000e+000,0,,0,
1467259061.327,,-5.020808e+004,2.699941e+001,-4.018708e-002,7.770588e-004,3,9.934229e-001,1.933603e+000,,,,,,,,,,,,,,64,2,3.000000e+000,1.491547e-003,0.000000e+000,0,,0,
1467259134.008,,-4.518461e+004,2.699997e+001,-4.081777e-002,7.440789e-004,3,9.941210e-001,1.822929e+000,,,,,,,,,,,,,,64,2,3.000000e+000,2.990723e-003,0.000000e+000,0,,0,
1467259205.859,,-4.016780e+004,2.699866e+001,-4.170048e-002,8.769337e-004,3,9.933537e-001,2.102934e+000,,,,,,,,,,,,,,64,2,3.000000e+000,2.250671e-003,0.000000e+000,0,,0,
1467259279.250,,-3.514803e+004,2.700016e+001,-4.280815e-002,7.209930e-004,3,9.946460e-001,1.684242e+000,,,,,,,,,,,,,,64,2,3.000000e+000,7.495880e-004,0.000000e+000,0,,0,
1467259351.150,,-3.012529e+004,2.699959e+001,-4.398364e-002,8.294025e-004,3,9.952502e-001,1.885707e+000,,,,,,,,,,,,,,64,2,3.000000e+000,3.740311e-003,0.000000e+000,0,,0,
1467259423.121,,-2.510553e+004,2.699978e+001,-4.543608e-002,9.696278e-004,3,9.956912e-001,2.134048e+000,,,,,,,,,,,,,,64,2,3.000000e+000,5.250931e-003,0.000000e+000,0,,0,
1467259495.342,,-2.008427e+004,2.699997e+001,-4.703860e-002,8.617950e-004,3,9.964324e-001,1.832102e+000,,,,,,,,,,,,,,64,2,3.000000e+000,1.501083e-003,0.000000e+000,0,,0,
1467259567.142,,-1.506569e+004,2.699997e+001,-4.952982e-002,1.037076e-003,3,9.964895e-001,2.093841e+000,,,,,,,,,,,,,,64,2,3.000000e+000,7.495880e-004,0.000000e+000,0,,0,
1467259678.536,,-1.005021e+004,2.700016e+001,-5.304102e-002,1.148354e-003,3,9.967734e-001,2.165030e+000,,,,,,,,,,,,,,64,2,3.000000e+000,4.491806e-003,0.000000e+000,0,,0,
1467259736.916,,-8.041122e+003,2.699922e+001,-5.517283e-002,1.362571e-003,3,9.967619e-001,2.469641e+000,,,,,,,,,,,,,,64,2,3.000000e+000,2.241135e-003,0.000000e+000,0,,0,
1467259838.227,,-6.025651e+003,2.699791e+001,-5.803820e-002,1.562995e-003,3,9.966727e-001,2.693045e+000,,,,,,,,,,,,,,64,2,3.000000e+000,3.000259e-003,0.000000e+000,0,,0,
1467259896.678,,-4.017372e+003,2.699960e+001,-6.159323e-002,1.574356e-003,3,9.971215e-001,2.556053e+000,,,,,,,,,,,,,,64,2,3.000000e+000,4.499435e-003,0.000000e+000,0,,0,
1467259954.318,,-2.009168e+003,2.699978e+001,-6.784289e-002,1.632268e-003,3,9.972099e-001,2.405954e+000,,,,,,,,,,,,,,64,2,3.000000e+000,1.501083e-003,0.000000e+000,0,,0,
1467260013.289,,-5.634359e-001,2.700034e+001,-7.385193e-002,1.597176e-003,3,9.971581e-001,2.162673e+000,,,,,,,,,,,,,,64,2,3.000000e+000,3.000259e-003,0.000000e+000,0,,0,
1467260077.870,,2.009243e+003,2.699903e+001,-6.686694e-002,1.667382e-003,3,9.970204e-001,2.493582e+000,,,,,,,,,,,,,,64,2,3.000000e+000,6.000519e-003,0.000000e+000,0,,0,
1467260135.600,,4.017521e+003,2.699922e+001,-5.854722e-002,1.487041e-003,3,9.970137e-001,2.539900e+000,,,,,,,,,,,,,,64,2,3.000000e+000,2.241135e-003,0.000000e+000,0,,0,
1467260193.561,,6.025503e+003,2.700034e+001,-5.280630e-002,1.335096e-003,3,9.971604e-001,2.528290e+000,,,,,,,,,,,,,,64,2,3.000000e+000,7.499695e-003,0.000000e+000,0,,0,
1467260294.132,,8.040232e+003,2.699847e+001,-4.833093e-002,1.250621e-003,3,9.969674e-001,2.587620e+000,,,,,,,,,,,,,,64,2,3.000000e+000,3.749847e-003,0.000000e+000,0,,0,
1467260350.882,,1.004666e+004,2.699903e+001,-4.474285e-002,1.172401e-003,3,9.970109e-001,2.620310e+000,,,,,,,,,,,,,,64,2,3.000000e+000,3.000259e-003,0.000000e+000,0,,0,