File: SP-M4-239-3-0104-#4/Irradiated/MH45K.dc.dat
[Header]
TITLE,MPMS DC Measurement
BYAPP,MPMS Measurement,2.1,Summary
FILEOPENTIME, 1467271387.145000 6/30/2016, 2:23:07 AM

INFO, APPNAME, MPMS MultiVu Application, Revision 1.60,  Build 081

INFO, NAME, tb11c
INFO, WEIGHT, 0.100
INFO, AREA, 1.000
INFO, LENGTH, 1.000
INFO, SHAPE, 1
INFO, COMMENT, 650C in 0.1% O2 in AR, single xtal, H//ab, lN2 quench
INFO, SEQUENCE FILE: Sequence_MT_5_27_77_45.seq


INFO, BACKGROUND DATA FILE:, None


STARTUPAXIS,X,4,LINEAR,AUTO,0.000000,0.000000
STARTUPAXIS,Y1,5,LINEAR,AUTO,0.000000,0.000000


STARTUPGROUP,Longitudinal
FIELDGROUP,Longitudinal,1,2,3,4,5,6,7,8,9,15,16,17,18,27,28
FIELDGROUP,Transverse,1,2,3,4,10,11,12,13,14,19,20,21,22,27,28

PLOT_APPEARANCE,ALL,HORZ_GRID_ON,VERT_GRID_ON,MARKERS_AND_LINES

[Data]
Time,Comment,Field (Oe),Temperature (K),Long Moment (emu),Long Scan Std Dev,Long Algorithm,Long Reg Fit,Long Percent Error (%),Trans Moment (emu),Trans Scan Std Dev,Trans Algorithm,Trans Reg Fit,Trans Percent Error (%),Long Moment [w/o ABS] (emu),Long Scan Std Dev [w/o ABS],Long Reg Fit [w/o ABS],Long Percent Error [w/o ABS] (%),Trans Moment [w/o ABS] (emu),Trans Scan Std Dev [w/o ABS],Trans Reg Fit [w/o ABS],Trans Percent Error [w/o ABS] (%),Points per Scan,Scans per Measurement,Scan Length (cm),Delta Temp (K),Rot Position (deg),Error,EC Comp. Running,Using ABS,
1467271387.145,,1.000000e+003,4.499823e+001,-3.237950e-002,1.067632e-004,3,9.981710e-001,3.297248e-001,,,,,,,,,,,,,,64,2,3.000000e+000,1.130676e-002,0.000000e+000,0,,0,
1467271440.515,,2.008724e+003,4.499399e+001,-3.154440e-002,8.568283e-004,3,9.977270e-001,2.716261e+000,,,,,,,,,,,,,,64,2,3.000000e+000,1.318741e-002,0.000000e+000,0,,0,
1467271494.256,,3.012825e+003,4.499870e+001,-2.899779e-002,6.538807e-004,3,9.963976e-001,2.254933e+000,,,,,,,,,,,,,,64,2,3.000000e+000,5.657196e-003,0.000000e+000,0,,0,
1467271548.266,,4.017003e+003,4.499728e+001,-2.721949e-002,5.400816e-004,3,9.957525e-001,1.984173e+000,,,,,,,,,,,,,,64,2,3.000000e+000,5.649567e-003,0.000000e+000,0,,0,
1467271601.157,,5.021401e+003,4.499635e+001,-2.583379e-002,4.521962e-004,3,9.946662e-001,1.750406e+000,,,,,,,,,,,,,,64,2,3.000000e+000,5.649567e-003,0.000000e+000,0,,0,
1467271654.047,,6.025207e+003,4.499493e+001,-2.469953e-002,4.451339e-004,3,9.944699e-001,1.802196e+000,,,,,,,,,,,,,,64,2,3.000000e+000,7.541656e-003,0.000000e+000,0,,0,
1467271707.398,,7.029309e+003,4.499587e+001,-2.368528e-002,4.325847e-004,3,9.944914e-001,1.826386e+000,,,,,,,,,,,,,,64,2,3.000000e+000,7.541656e-003,0.000000e+000,0,,0,
1467271804.580,,8.040083e+003,4.500199e+001,-2.267224e-002,4.094803e-004,3,9.951588e-001,1.806087e+000,,,,,,,,,,,,,,64,2,3.000000e+000,7.530212e-003,0.000000e+000,0,,0,
1467271857.932,,9.042556e+003,4.500058e+001,-2.184645e-002,3.981982e-004,3,9.942826e-001,1.822714e+000,,,,,,,,,,,,,,64,2,3.000000e+000,9.410858e-003,0.000000e+000,0,,0,
1467271911.833,,1.004606e+004,4.500058e+001,-2.101243e-002,3.959881e-004,3,9.949411e-001,1.884542e+000,,,,,,,,,,,,,,64,2,3.000000e+000,5.657196e-003,0.000000e+000,0,,0,
1467272023.361,,1.506806e+004,4.499822e+001,-1.774551e-002,7.992439e-004,3,9.905424e-001,4.503922e+000,,,,,,,,,,,,,,64,2,3.000000e+000,1.130295e-002,0.000000e+000,0,,0,
1467272095.051,,2.008724e+004,4.499775e+001,-1.451137e-002,6.347539e-004,3,9.882702e-001,4.374182e+000,,,,,,,,,,,,,,64,2,3.000000e+000,3.768921e-003,0.000000e+000,0,,0,
1467272167.187,,2.510849e+004,4.499964e+001,-1.159701e-002,6.048013e-004,3,9.836209e-001,5.215147e+000,,,,,,,,,,,,,,64,2,3.000000e+000,7.537842e-003,0.000000e+000,0,,0,
1467272240.043,,3.012678e+004,4.500011e+001,-8.931396e-003,5.450879e-004,3,9.756025e-001,6.103054e+000,,,,,,,,,,,,,,64,2,3.000000e+000,1.130295e-002,0.000000e+000,0,,0,
1467272311.228,,3.514951e+004,4.499870e+001,-6.430375e-003,5.516904e-004,3,9.656736e-001,8.579443e+000,,,,,,,,,,,,,,64,2,3.000000e+000,7.541656e-003,0.000000e+000,0,,0,
1467272426.741,,4.017150e+004,4.499681e+001,-3.169239e-003,2.445996e-004,3,9.385563e-001,7.717927e+000,,,,,,,,,,,,,,64,2,3.000000e+000,5.653381e-003,0.000000e+000,0,,0,
1467272497.528,,4.519054e+004,4.499728e+001,-2.131961e-003,5.079857e-004,3,8.825101e-001,2.382715e+001,,,,,,,,,,,,,,64,2,3.000000e+000,1.880646e-003,0.000000e+000,0,,0,
1467272652.571,,5.021253e+004,4.499870e+001,9.834504e-004,6.216812e-005,3,7.777539e-001,6.321429e+000,,,,,,,,,,,,,,64,2,3.000000e+000,5.649567e-003,0.000000e+000,0,,0,
1467272765.705,,5.523452e+004,4.499775e+001,2.341308e-003,1.589412e-004,3,9.005333e-001,6.788564e+000,,,,,,,,,,,,,,64,2,3.000000e+000,1.130295e-002,0.000000e+000,0,,0,
1467272835.848,,6.025355e+004,4.500058e+001,3.367319e-003,2.513322e-004,3,9.134690e-001,7.463866e+000,,,,,,,,,,,,,,64,2,3.000000e+000,3.776550e-003,0.000000e+000,0,,0,
1467272907.451,,6.527704e+004,4.499681e+001,4.777928e-003,3.117981e-004,3,9.374672e-001,6.525802e+000,,,,,,,,,,,,,,64,2,3.000000e+000,7.530212e-003,0.000000e+000,0,,0,
1467272977.313,,7.029458e+004,4.499869e+001,6.444375e-003,2.563101e-004,3,9.327525e-001,3.977269e+000,,,,,,,,,,,,,,64,2,3.000000e+000,3.768921e-003,0.000000e+000,0,,0,
1467273113.528,,6.526962e+004,4.499681e+001,2.039759e-002,1.541060e-004,3,9.869235e-001,7.555107e-001,,,,,,,,,,,,,,64,2,3.000000e+000,5.653381e-003,0.000000e+000,0,,0,
1467273187.139,,6.025059e+004,4.499728e+001,2.082040e-002,6.482976e-005,3,9.881470e-001,3.113762e-001,,,,,,,,,,,,,,64,2,3.000000e+000,1.130676e-002,0.000000e+000,0,,0,
1467273261.210,,5.523155e+004,4.499917e+001,2.062552e-002,1.951004e-004,3,9.887108e-001,9.459175e-001,,,,,,,,,,,,,,64,2,3.000000e+000,5.657196e-003,0.000000e+000,0,,0,
1467273333.441,,5.020956e+004,4.499917e+001,2.077732e-002,3.637299e-004,3,9.892910e-001,1.750611e+000,,,,,,,,,,,,,,64,2,3.000000e+000,7.537842e-003,0.000000e+000,0,,0,
1467273406.622,,4.518757e+004,4.499775e+001,2.097017e-002,3.917747e-004,3,9.903984e-001,1.868248e+000,,,,,,,,,,,,,,64,2,3.000000e+000,1.880646e-003,0.000000e+000,0,,0,
1467273479.483,,4.017151e+004,4.499728e+001,2.128984e-002,3.952084e-004,3,9.913160e-001,1.856324e+000,,,,,,,,,,,,,,64,2,3.000000e+000,1.880646e-003,0.000000e+000,0,,0,
1467273552.113,,3.515025e+004,4.499916e+001,2.169229e-002,4.408613e-004,3,9.921046e-001,2.032341e+000,,,,,,,,,,,,,,64,2,3.000000e+000,1.888275e-003,0.000000e+000,0,,0,
1467273623.914,,3.012751e+004,4.499540e+001,2.222141e-002,5.051062e-004,3,9.936997e-001,2.273062e+000,,,,,,,,,,,,,,64,2,3.000000e+000,5.653381e-003,0.000000e+000,0,,0,
1467273696.085,,2.510923e+004,4.499728e+001,2.278791e-002,5.592189e-004,3,9.942844e-001,2.454016e+000,,,,,,,,,,,,,,64,2,3.000000e+000,1.880646e-003,0.000000e+000,0,,0,
1467273768.975,,2.008871e+004,4.500153e+001,2.361305e-002,4.208047e-004,3,9.940200e-001,1.782085e+000,,,,,,,,,,,,,,64,2,3.000000e+000,1.888275e-003,0.000000e+000,0,,0,
1467273841.276,,1.506657e+004,4.499916e+001,2.463642e-002,5.360816e-004,3,9.956730e-001,2.175972e+000,,,,,,,,,,,,,,64,2,3.000000e+000,7.530212e-003,0.000000e+000,0,,0,
1467273952.599,,1.004814e+004,4.499681e+001,2.605911e-002,5.746394e-004,3,9.957975e-001,2.205138e+000,,,,,,,,,,,,,,64,2,3.000000e+000,1.129913e-002,0.000000e+000,0,,0,
1467274012.040,,8.039639e+003,4.499822e+001,2.677614e-002,6.206980e-004,3,9.962730e-001,2.318101e+000,,,,,,,,,,,,,,64,2,3.000000e+000,7.541656e-003,0.000000e+000,0,,0,
1467274113.701,,6.025800e+003,4.499540e+001,2.777001e-002,5.395007e-004,3,9.951670e-001,1.942746e+000,,,,,,,,,,,,,,64,2,3.000000e+000,9.418488e-003,0.000000e+000,0,,0,
1467274173.061,,4.017595e+003,4.500011e+001,2.922702e-002,5.422060e-004,3,9.963895e-001,1.855153e+000,,,,,,,,,,,,,,64,2,3.000000e+000,1.317978e-002,0.000000e+000,0,,0,
1467274231.732,,2.009317e+003,4.499870e+001,3.230794e-002,5.823430e-004,3,9.966108e-001,1.802477e+000,,,,,,,,,,,,,,64,2,3.000000e+000,7.541656e-003,0.000000e+000,0,,0,
1467274290.403,,4.892998e-001,4.499775e+001,3.849631e-002,5.817819e-004,3,9.964124e-001,1.511267e+000,,,,,,,,,,,,,,64,2,3.000000e+000,3.768921e-003,0.000000e+000,0,,0,
1467274355.703,,-2.009391e+003,4.499963e+001,3.137818e-002,5.261152e-004,3,9.946847e-001,1.676691e+000,,,,,,,,,,,,,,64,2,3.000000e+000,7.530212e-003,0.000000e+000,0,,0,
1467274415.254,,-4.017595e+003,4.500105e+001,2.722044e-002,5.226947e-004,3,9.962174e-001,1.920228e+000,,,,,,,,,,,,,,64,2,3.000000e+000,9.410858e-003,0.000000e+000,0,,0,
1467274474.455,,-6.025800e+003,4.499728e+001,2.475511e-002,4.273427e-004,3,9.953945e-001,1.726281e+000,,,,,,,,,,,,,,64,2,3.000000e+000,1.130676e-002,0.000000e+000,0,,0,
1467274577.066,,-8.038897e+003,4.499869e+001,2.271180e-002,4.286519e-004,3,9.950068e-001,1.887353e+000,,,,,,,,,,,,,,64,2,3.000000e+000,0.000000e+000,0.000000e+000,0,,0,
1467274635.206,,-1.004606e+004,4.499916e+001,2.099457e-002,3.512900e-004,3,9.948181e-001,1.673242e+000,,,,,,,,,,,,,,64,2,3.000000e+000,5.657196e-003,0.000000e+000,0,,0,
1467274746.929,,-1.506865e+004,4.499917e+001,1.781475e-002,8.319972e-004,3,9.895322e-001,4.670272e+000,,,,,,,,,,,,,,64,2,3.000000e+000,5.657196e-003,0.000000e+000,0,,0,
1467274817.330,,-2.009020e+004,4.499681e+001,1.453884e-002,6.230193e-004,3,9.866413e-001,4.285206e+000,,,,,,,,,,,,,,64,2,3.000000e+000,9.429932e-003,0.000000e+000,0,,0,
1467274929.771,,-2.511071e+004,4.500105e+001,1.065013e-002,1.824754e-004,3,9.881139e-001,1.713364e+000,,,,,,,,,,,,,,64,2,3.000000e+000,5.649567e-003,0.000000e+000,0,,0,
1467275001.312,,-3.012975e+004,4.499916e+001,8.918508e-003,5.250023e-004,3,9.764108e-001,5.886660e+000,,,,,,,,,,,,,,64,2,3.000000e+000,5.657196e-003,0.000000e+000,0,,0,
1467275072.542,,-3.515248e+004,4.499964e+001,6.583560e-003,4.088202e-004,3,9.641087e-001,6.209713e+000,,,,,,,,,,,,,,64,2,3.000000e+000,5.657196e-003,0.000000e+000,0,,0,
1467275185.904,,-4.017298e+004,4.499587e+001,3.480729e-003,1.041954e-004,3,9.457923e-001,2.993494e+000,,,,,,,,,,,,,,64,2,3.000000e+000,1.880646e-003,0.000000e+000,0,,0,
1467275257.754,,-4.519350e+004,4.499681e+001,2.143160e-003,4.488873e-004,3,8.834200e-001,2.094511e+001,,,,,,,,,,,,,,64,2,3.000000e+000,7.530212e-003,0.000000e+000,0,,0,
1467275435.356,,-5.021252e+004,4.499587e+001,-9.105415e-004,5.214944e-005,3,7.636442e-001,5.727300e+000,,,,,,,,,,,,,,64,2,3.000000e+000,1.880646e-003,0.000000e+000,0,,0,
1467275547.727,,-5.523749e+004,4.499540e+001,-2.266048e-003,1.067160e-004,3,8.882520e-001,4.709345e+000,,,,,,,,,,,,,,64,2,3.000000e+000,1.130295e-002,0.000000e+000,0,,0,
1467275617.248,,-6.025207e+004,4.499775e+001,-3.300960e-003,2.687647e-004,3,9.097719e-001,8.142016e+000,,,,,,,,,,,,,,64,2,3.000000e+000,7.541656e-003,0.000000e+000,0,,0,
1467275688.219,,-6.527852e+004,4.499963e+001,-4.856574e-003,2.603849e-004,3,9.389195e-001,5.361493e+000,,,,,,,,,,,,,,64,2,3.000000e+000,1.130295e-002,0.000000e+000,0,,0,
1467275821.120,,-7.029012e+004,4.499634e+001,-7.440962e-003,3.925199e-004,3,9.576534e-001,5.275123e+000,,,,,,,,,,,,,,64,2,3.000000e+000,1.880646e-003,0.000000e+000,0,,0,
1467275977.284,,-6.527111e+004,4.500011e+001,-1.999112e-002,7.407836e-005,3,9.852527e-001,3.705562e-001,,,,,,,,,,,,,,64,2,3.000000e+000,3.776550e-003,0.000000e+000,0,,0,
1467276050.634,,-6.024762e+004,4.499964e+001,-2.046099e-002,3.376094e-004,3,9.871523e-001,1.650015e+000,,,,,,,,,,,,,,64,2,3.000000e+000,5.657196e-003,0.000000e+000,0,,0,
1467276125.725,,-5.522859e+004,4.500011e+001,-2.053851e-002,4.181046e-004,3,9.889388e-001,2.035710e+000,,,,,,,,,,,,,,64,2,3.000000e+000,5.657196e-003,0.000000e+000,0,,0,
1467276199.576,,-5.020660e+004,4.499775e+001,-2.072377e-002,3.393322e-004,3,9.898068e-001,1.637406e+000,,,,,,,,,,,,,,64,2,3.000000e+000,1.880646e-003,0.000000e+000,0,,0,
1467276272.826,,-4.518461e+004,4.500105e+001,-2.092186e-002,4.056990e-004,3,9.912595e-001,1.939115e+000,,,,,,,,,,,,,,64,2,3.000000e+000,5.657196e-003,0.000000e+000,0,,0,
1467276345.047,,-4.016780e+004,4.500010e+001,-2.119888e-002,4.168653e-004,3,9.918076e-001,1.966449e+000,,,,,,,,,,,,,,64,2,3.000000e+000,5.649567e-003,0.000000e+000,0,,0,
1467276417.388,,-3.514729e+004,4.499681e+001,-2.153777e-002,5.175567e-004,3,9.908045e-001,2.403019e+000,,,,,,,,,,,,,,64,2,3.000000e+000,9.429932e-003,0.000000e+000,0,,0,
1467276490.359,,-3.012455e+004,4.499681e+001,-2.213370e-002,4.879973e-004,3,9.937273e-001,2.204771e+000,,,,,,,,,,,,,,64,2,3.000000e+000,2.070999e-002,0.000000e+000,0,,0,
1467276561.799,,-2.510626e+004,4.499869e+001,-2.285726e-002,5.201988e-004,3,9.943937e-001,2.275858e+000,,,,,,,,,,,,,,64,2,3.000000e+000,3.768921e-003,0.000000e+000,0,,0,
1467276633.260,,-2.008575e+004,4.499822e+001,-2.368252e-002,4.981757e-004,3,9.946342e-001,2.103559e+000,,,,,,,,,,,,,,64,2,3.000000e+000,3.768921e-003,0.000000e+000,0,,0,
1467276705.211,,-1.506658e+004,4.500293e+001,-2.466999e-002,5.302837e-004,3,9.951640e-001,2.149509e+000,,,,,,,,,,,,,,64,2,3.000000e+000,7.537842e-003,0.000000e+000,0,,0,
1467276818.254,,-1.004873e+004,4.499870e+001,-2.605385e-002,5.300045e-004,3,9.955631e-001,2.034265e+000,,,,,,,,,,,,,,64,2,3.000000e+000,5.657196e-003,0.000000e+000,0,,0,
1467276877.675,,-8.040084e+003,4.500152e+001,-2.682923e-002,6.782548e-004,3,9.961417e-001,2.528044e+000,,,,,,,,,,,,,,64,2,3.000000e+000,3.761292e-003,0.000000e+000,0,,0,
1467276980.476,,-6.025503e+003,4.499728e+001,-2.777590e-002,5.808679e-004,3,9.948484e-001,2.091266e+000,,,,,,,,,,,,,,64,2,3.000000e+000,5.649567e-003,0.000000e+000,0,,0,
1467277039.226,,-4.017373e+003,4.499681e+001,-2.925084e-002,5.704576e-004,3,9.961842e-001,1.950226e+000,,,,,,,,,,,,,,64,2,3.000000e+000,5.653381e-003,0.000000e+000,0,,0,
1467277098.407,,-2.009094e+003,4.499869e+001,-3.241200e-002,7.311846e-004,3,9.962776e-001,2.255907e+000,,,,,,,,,,,,,,64,2,3.000000e+000,3.768921e-003,0.000000e+000,0,,0,
1467277157.377,,-5.486088e-001,4.500058e+001,-3.847565e-002,6.448125e-004,3,9.962003e-001,1.675898e+000,,,,,,,,,,,,,,64,2,3.000000e+000,9.418488e-003,0.000000e+000,0,,0,
1467277223.288,,2.009169e+003,4.499822e+001,-3.139946e-002,5.809706e-004,3,9.955776e-001,1.850257e+000,,,,,,,,,,,,,,64,2,3.000000e+000,3.768921e-003,0.000000e+000,0,,0,
1467277281.739,,4.017373e+003,4.500058e+001,-2.722104e-002,4.624339e-004,3,9.957163e-001,1.698810e+000,,,,,,,,,,,,,,64,2,3.000000e+000,3.776550e-003,0.000000e+000,0,,0,
1467277339.889,,6.025651e+003,4.500152e+001,-2.479928e-002,5.251721e-004,3,9.945397e-001,2.117691e+000,,,,,,,,,,,,,,64,2,3.000000e+000,7.537842e-003,0.000000e+000,0,,0,
1467277441.740,,8.039787e+003,4.499775e+001,-2.268432e-002,4.699453e-004,3,9.935124e-001,2.071674e+000,,,,,,,,,,,,,,64,2,3.000000e+000,3.768921e-003,0.000000e+000,0,,0,
1467277499.361,,1.004606e+004,4.499822e+001,-2.099945e-002,3.139901e-004,3,9.945569e-001,1.495230e+000,,,,,,,,,,,,,,64,2,3.000000e+000,7.541656e-003,0.000000e+000,0,,0,