File: SP-M4-239-3-0104-#4/Irradiated/MH77K SPM4-239-3-0104-#4-1Cu.txt
[Header]
TITLE,MPMS DC Measurement
BYAPP,MPMS Measurement,2.1,Summary
FILEOPENTIME, 1467262568.484000 6/29/2016, 11:56:08 PM

INFO, APPNAME, MPMS MultiVu Application, Revision 1.60,  Build 081

INFO, NAME, tb11c
INFO, WEIGHT, 0.100
INFO, AREA, 1.000
INFO, LENGTH, 1.000
INFO, SHAPE, 1
INFO, COMMENT, 650C in 0.1% O2 in AR, single xtal, H//ab, lN2 quench
INFO, SEQUENCE FILE: Sequence_MT_5_27_77_45.seq


INFO, BACKGROUND DATA FILE:, None


STARTUPAXIS,X,4,LINEAR,AUTO,0.000000,0.000000
STARTUPAXIS,Y1,5,LINEAR,AUTO,0.000000,0.000000


STARTUPGROUP,Longitudinal
FIELDGROUP,Longitudinal,1,2,3,4,5,6,7,8,9,15,16,17,18,27,28
FIELDGROUP,Transverse,1,2,3,4,10,11,12,13,14,19,20,21,22,27,28

PLOT_APPEARANCE,ALL,HORZ_GRID_ON,VERT_GRID_ON,MARKERS_AND_LINES

[Data]
Time,Comment,Field (Oe),Temperature (K),Long Moment (emu),Long Scan Std Dev,Long Algorithm,Long Reg Fit,Long Percent Error (%),Trans Moment (emu),Trans Scan Std Dev,Trans Algorithm,Trans Reg Fit,Trans Percent Error (%),Long Moment [w/o ABS] (emu),Long Scan Std Dev [w/o ABS],Long Reg Fit [w/o ABS],Long Percent Error [w/o ABS] (%),Trans Moment [w/o ABS] (emu),Trans Scan Std Dev [w/o ABS],Trans Reg Fit [w/o ABS],Trans Percent Error [w/o ABS] (%),Points per Scan,Scans per Measurement,Scan Length (cm),Delta Temp (K),Rot Position (deg),Error,EC Comp. Running,Using ABS,
1467262568.484,,1.000000e+003,7.699236e+001,-1.684258e-003,1.872538e-005,3,9.926267e-001,1.111788e+000,,,,,,,,,,,,,,64,2,3.000000e+000,2.404022e-002,0.000000e+000,0,,0,
1467262621.015,,2.008724e+003,7.699035e+001,-1.305194e-003,1.284927e-004,3,9.606445e-001,9.844718e+000,,,,,,,,,,,,,,64,2,3.000000e+000,2.602386e-002,0.000000e+000,0,,0,
1467262673.825,,3.012677e+003,7.699285e+001,-7.278911e-004,2.214756e-004,3,7.980388e-001,3.042702e+001,,,,,,,,,,,,,,64,2,3.000000e+000,1.802826e-002,0.000000e+000,0,,0,
1467262768.906,,4.017003e+003,7.699335e+001,-5.617002e-004,2.443138e-005,3,9.532391e-001,4.349542e+000,,,,,,,,,,,,,,64,2,3.000000e+000,1.604462e-002,0.000000e+000,0,,0,
1467262864.837,,5.021104e+003,7.699686e+001,-3.424381e-004,2.182927e-005,3,9.179850e-001,6.374661e+000,,,,,,,,,,,,,,64,2,3.000000e+000,2.404785e-002,0.000000e+000,0,,0,
1467262960.718,,6.025207e+003,7.699084e+001,-1.445417e-004,1.736395e-005,3,7.988392e-001,1.201310e+001,,,,,,,,,,,,,,64,2,3.000000e+000,8.010864e-003,0.000000e+000,0,,0,
1467263119.510,,7.028864e+003,7.699536e+001,1.334627e-004,6.015753e-006,3,7.238578e-001,4.507442e+000,,,,,,,,,,,,,,64,2,3.000000e+000,1.403046e-002,0.000000e+000,0,,0,
1467263279.072,,8.040083e+003,7.700087e+001,2.792922e-004,1.954780e-005,3,8.708136e-001,6.999051e+000,,,,,,,,,,,,,,64,2,3.000000e+000,6.019592e-003,0.000000e+000,0,,0,
1467263376.093,,9.042556e+003,7.699585e+001,4.389731e-004,2.466576e-005,3,9.022786e-001,5.618969e+000,,,,,,,,,,,,,,64,2,3.000000e+000,1.202393e-002,0.000000e+000,0,,0,
1467263471.523,,1.004755e+004,7.698934e+001,6.150410e-004,1.887277e-005,3,9.225693e-001,3.068539e+000,,,,,,,,,,,,,,64,2,3.000000e+000,1.000977e-002,0.000000e+000,0,,0,
1467263646.477,,1.506866e+004,7.698685e+001,1.433847e-003,1.310224e-005,3,9.494166e-001,9.137823e-001,,,,,,,,,,,,,,64,2,3.000000e+000,2.603149e-002,0.000000e+000,0,,0,
1467263804.199,,2.008872e+004,7.699235e+001,2.114630e-003,1.690368e-005,3,9.602820e-001,7.993685e-001,,,,,,,,,,,,,,64,2,3.000000e+000,8.010864e-003,0.000000e+000,0,,0,
1467263918.010,,2.510774e+004,7.698685e+001,2.722084e-003,4.523476e-005,3,9.589362e-001,1.661770e+000,,,,,,,,,,,,,,64,2,3.000000e+000,4.808044e-002,0.000000e+000,0,,0,
1467263989.261,,3.012751e+004,7.698834e+001,3.118679e-003,7.976423e-005,3,9.465567e-001,2.557629e+000,,,,,,,,,,,,,,64,2,3.000000e+000,1.400757e-002,0.000000e+000,0,,0,
1467264060.781,,3.515174e+004,7.698885e+001,4.207192e-003,6.227714e-004,3,9.116018e-001,1.480254e+001,,,,,,,,,,,,,,64,2,3.000000e+000,1.602173e-002,0.000000e+000,0,,0,
1467264132.412,,4.017077e+004,7.698885e+001,4.305429e-003,9.935132e-005,3,9.536989e-001,2.307582e+000,,,,,,,,,,,,,,64,2,3.000000e+000,2.805328e-002,0.000000e+000,0,,0,
1467264202.663,,4.519054e+004,7.699185e+001,4.955121e-003,1.920941e-005,3,9.591812e-001,3.876679e-001,,,,,,,,,,,,,,64,2,3.000000e+000,2.603149e-002,0.000000e+000,0,,0,
1467264273.413,,5.021253e+004,7.698885e+001,5.513679e-003,1.741610e-004,3,9.675542e-001,3.158707e+000,,,,,,,,,,,,,,64,2,3.000000e+000,3.406525e-002,0.000000e+000,0,,0,
1467264344.224,,5.523452e+004,7.699736e+001,6.010463e-003,2.055242e-004,3,9.646199e-001,3.419440e+000,,,,,,,,,,,,,,64,2,3.000000e+000,1.000977e-002,0.000000e+000,0,,0,
1467264415.015,,6.025355e+004,7.699035e+001,6.632756e-003,1.719236e-004,3,9.658394e-001,2.592038e+000,,,,,,,,,,,,,,64,2,3.000000e+000,1.402283e-002,0.000000e+000,0,,0,
1467264484.976,,6.527406e+004,7.699036e+001,7.116537e-003,1.650599e-004,3,9.634928e-001,2.319385e+000,,,,,,,,,,,,,,64,2,3.000000e+000,1.803589e-002,0.000000e+000,0,,0,
1467264554.966,,7.029309e+004,7.699335e+001,7.163926e-003,4.992373e-004,3,9.573681e-001,6.968767e+000,,,,,,,,,,,,,,64,2,3.000000e+000,1.402283e-002,0.000000e+000,0,,0,
1467264667.789,,6.527259e+004,7.700137e+001,7.126055e-003,3.454329e-005,3,9.630132e-001,4.847464e-001,,,,,,,,,,,,,,64,2,3.000000e+000,1.602173e-002,0.000000e+000,0,,0,
1467264740.960,,6.025207e+004,7.699536e+001,6.543772e-003,4.442476e-005,3,9.618773e-001,6.788861e-001,,,,,,,,,,,,,,64,2,3.000000e+000,1.603699e-002,0.000000e+000,0,,0,
1467264814.031,,5.523304e+004,7.698634e+001,6.235545e-003,7.133552e-005,3,9.643719e-001,1.144014e+000,,,,,,,,,,,,,,64,2,3.000000e+000,1.802063e-002,0.000000e+000,0,,0,
1467264885.392,,5.021105e+004,7.700037e+001,5.783680e-003,7.388870e-006,3,9.606162e-001,1.277538e-001,,,,,,,,,,,,,,64,2,3.000000e+000,2.806091e-002,0.000000e+000,0,,0,
1467264957.612,,4.518905e+004,7.699084e+001,5.257800e-003,1.118732e-004,3,9.680248e-001,2.127757e+000,,,,,,,,,,,,,,64,2,3.000000e+000,1.402283e-002,0.000000e+000,0,,0,
1467265030.503,,4.017002e+004,7.699535e+001,4.689622e-003,1.133223e-005,3,9.664363e-001,2.416449e-001,,,,,,,,,,,,,,64,2,3.000000e+000,1.802826e-002,0.000000e+000,0,,0,
1467265102.874,,3.514951e+004,7.699686e+001,4.194879e-003,7.664602e-005,3,9.700407e-001,1.827133e+000,,,,,,,,,,,,,,64,2,3.000000e+000,2.003479e-002,0.000000e+000,0,,0,
1467265175.215,,3.012677e+004,7.699385e+001,3.726523e-003,1.296740e-005,3,9.687049e-001,3.479758e-001,,,,,,,,,,,,,,64,2,3.000000e+000,1.604462e-002,0.000000e+000,0,,0,
1467265247.405,,2.510775e+004,7.699135e+001,3.223689e-003,9.114256e-005,3,9.721196e-001,2.827276e+000,,,,,,,,,,,,,,64,2,3.000000e+000,1.802063e-002,0.000000e+000,0,,0,
1467265320.376,,2.008723e+004,7.699136e+001,2.830474e-003,9.150196e-005,3,9.723352e-001,3.232744e+000,,,,,,,,,,,,,,64,2,3.000000e+000,1.803589e-002,0.000000e+000,0,,0,
1467265392.667,,1.506569e+004,7.698885e+001,2.464758e-003,8.840334e-005,3,9.735330e-001,3.586694e+000,,,,,,,,,,,,,,64,2,3.000000e+000,1.600647e-002,0.000000e+000,0,,0,
1467265505.330,,1.004725e+004,7.699886e+001,2.110132e-003,1.319509e-005,3,9.632218e-001,6.253206e-001,,,,,,,,,,,,,,64,2,3.000000e+000,1.401520e-002,0.000000e+000,0,,0,
1467265563.510,,8.039342e+003,7.699236e+001,1.966110e-003,1.153721e-005,3,9.668444e-001,5.868037e-001,,,,,,,,,,,,,,64,2,3.000000e+000,1.804352e-002,0.000000e+000,0,,0,
1467265728.622,,6.025651e+003,7.698984e+001,1.715949e-003,1.810429e-005,3,9.893338e-001,1.055060e+000,,,,,,,,,,,,,,64,2,3.000000e+000,8.010864e-003,0.000000e+000,0,,0,
1467265786.623,,4.017447e+003,7.699387e+001,1.704645e-003,1.500555e-004,3,9.443485e-001,8.802746e+000,,,,,,,,,,,,,,64,2,3.000000e+000,1.403046e-002,0.000000e+000,0,,0,
1467265846.113,,2.009242e+003,7.698885e+001,1.829706e-003,1.376279e-004,3,9.557338e-001,7.521857e+000,,,,,,,,,,,,,,64,2,3.000000e+000,2.204132e-002,0.000000e+000,0,,0,
1467265905.754,,4.596453e-001,7.699236e+001,3.756651e-003,1.603944e-004,3,9.775710e-001,4.269612e+000,,,,,,,,,,,,,,64,2,3.000000e+000,8.010864e-003,0.000000e+000,0,,0,
1467265991.545,,-2.009242e+003,7.698434e+001,1.190910e-003,4.616414e-005,3,9.757231e-001,3.876374e+000,,,,,,,,,,,,,,64,2,3.000000e+000,1.802063e-002,0.000000e+000,0,,0,
1467266115.386,,-4.017447e+003,7.699286e+001,5.396322e-004,2.299020e-005,3,9.465461e-001,4.260346e+000,,,,,,,,,,,,,,64,2,3.000000e+000,2.805328e-002,0.000000e+000,0,,0,
1467266193.967,,-6.025800e+003,7.699135e+001,2.268891e-004,3.426060e-005,3,8.372424e-001,1.510015e+001,,,,,,,,,,,,,,64,2,3.000000e+000,6.011963e-003,0.000000e+000,0,,0,
1467266296.118,,-8.038008e+003,7.698935e+001,-4.347266e-004,3.219623e-004,3,7.479579e-001,7.406089e+001,,,,,,,,,,,,,,64,2,3.000000e+000,3.205872e-002,0.000000e+000,0,,0,
1467266396.559,,-1.004547e+004,7.699036e+001,-5.949858e-004,3.869159e-005,3,9.032171e-001,6.502944e+000,,,,,,,,,,,,,,64,2,3.000000e+000,1.998901e-003,0.000000e+000,0,,0,
1467266549.882,,-1.506836e+004,7.699736e+001,-1.369764e-003,3.687364e-005,3,9.416310e-001,2.691970e+000,,,,,,,,,,,,,,64,2,3.000000e+000,2.003479e-002,0.000000e+000,0,,0,
1467266621.733,,-2.008946e+004,7.698785e+001,-1.809185e-003,1.342018e-004,3,9.088869e-001,7.417803e+000,,,,,,,,,,,,,,64,2,3.000000e+000,3.004456e-002,0.000000e+000,0,,0,
1467266693.234,,-2.511071e+004,7.700137e+001,-2.484264e-003,7.692541e-005,3,9.378265e-001,3.096507e+000,,,,,,,,,,,,,,64,2,3.000000e+000,3.205872e-002,0.000000e+000,0,,0,
1467266765.334,,-3.012975e+004,7.699686e+001,-3.124534e-003,8.638935e-005,3,9.407278e-001,2.764871e+000,,,,,,,,,,,,,,64,2,3.000000e+000,8.010864e-003,0.000000e+000,0,,0,
1467266836.985,,-3.515248e+004,7.699236e+001,-3.746639e-003,2.015421e-004,3,9.354511e-001,5.379277e+000,,,,,,,,,,,,,,64,2,3.000000e+000,1.603699e-002,0.000000e+000,0,,0,
1467266908.266,,-4.017298e+004,7.699435e+001,-4.365057e-003,9.003653e-005,3,9.524403e-001,2.062666e+000,,,,,,,,,,,,,,64,2,3.000000e+000,2.403259e-002,0.000000e+000,0,,0,
1467266979.797,,-4.519498e+004,7.699186e+001,-4.877503e-003,6.085577e-005,3,9.549438e-001,1.247683e+000,,,,,,,,,,,,,,64,2,3.000000e+000,3.807068e-002,0.000000e+000,0,,0,
1467267050.727,,-5.021105e+004,7.698935e+001,-5.456988e-003,2.536121e-005,3,9.583421e-001,4.647473e-001,,,,,,,,,,,,,,64,2,3.000000e+000,2.404022e-002,0.000000e+000,0,,0,
1467267120.388,,-5.523304e+004,7.699185e+001,-6.009424e-003,6.145900e-005,3,9.676963e-001,1.022710e+000,,,,,,,,,,,,,,64,2,3.000000e+000,2.204132e-002,0.000000e+000,0,,0,
1467267191.409,,-6.025355e+004,7.699036e+001,-6.497156e-003,3.804576e-005,3,9.609121e-001,5.855756e-001,,,,,,,,,,,,,,64,2,3.000000e+000,3.405762e-002,0.000000e+000,0,,0,
1467267262.509,,-6.527407e+004,7.699084e+001,-7.018847e-003,5.390911e-005,3,9.643101e-001,7.680622e-001,,,,,,,,,,,,,,64,2,3.000000e+000,1.402283e-002,0.000000e+000,0,,0,
1467267332.950,,-7.029605e+004,7.699936e+001,-7.494626e-003,5.903753e-005,3,9.585706e-001,7.877315e-001,,,,,,,,,,,,,,64,2,3.000000e+000,1.403809e-002,0.000000e+000,0,,0,
1467267446.283,,-6.527110e+004,7.699936e+001,-7.161309e-003,1.246809e-004,3,9.655545e-001,1.741035e+000,,,,,,,,,,,,,,64,2,3.000000e+000,8.033752e-003,0.000000e+000,0,,0,
1467267518.774,,-6.024614e+004,7.699586e+001,-6.812784e-003,1.901715e-004,3,9.677956e-001,2.791392e+000,,,,,,,,,,,,,,64,2,3.000000e+000,1.203156e-002,0.000000e+000,0,,0,
1467267591.055,,-5.522860e+004,7.699486e+001,-6.207115e-003,2.082548e-005,3,9.676938e-001,3.355098e-001,,,,,,,,,,,,,,64,2,3.000000e+000,1.803589e-002,0.000000e+000,0,,0,
1467267663.205,,-5.020956e+004,7.699435e+001,-5.717559e-003,3.604214e-006,3,9.620707e-001,6.303763e-002,,,,,,,,,,,,,,64,2,3.000000e+000,8.010864e-003,0.000000e+000,0,,0,
1467267735.556,,-4.518609e+004,7.698985e+001,-5.218267e-003,5.914981e-005,3,9.654486e-001,1.133515e+000,,,,,,,,,,,,,,64,2,3.000000e+000,2.001953e-002,0.000000e+000,0,,0,
1467267809.037,,-4.016780e+004,7.699937e+001,-4.698081e-003,6.164833e-005,3,9.638929e-001,1.312202e+000,,,,,,,,,,,,,,64,2,3.000000e+000,6.019592e-003,0.000000e+000,0,,0,
1467267881.628,,-3.514729e+004,7.699686e+001,-4.155691e-003,1.665986e-005,3,9.677044e-001,4.008926e-001,,,,,,,,,,,,,,64,2,3.000000e+000,8.026123e-003,0.000000e+000,0,,0,
1467267953.868,,-3.012455e+004,7.699185e+001,-3.745759e-003,1.079922e-004,3,9.692185e-001,2.883054e+000,,,,,,,,,,,,,,64,2,3.000000e+000,1.002502e-002,0.000000e+000,0,,0,
1467268026.749,,-2.510626e+004,7.699435e+001,-3.214804e-003,6.259893e-005,3,9.696345e-001,1.947209e+000,,,,,,,,,,,,,,64,2,3.000000e+000,1.002502e-002,0.000000e+000,0,,0,
1467268099.050,,-2.008501e+004,7.699435e+001,-2.799648e-003,4.273888e-005,3,9.667019e-001,1.526581e+000,,,,,,,,,,,,,,64,2,3.000000e+000,1.403809e-002,0.000000e+000,0,,0,
1467268172.360,,-1.506332e+004,7.699686e+001,-2.347660e-003,3.093842e-005,3,9.736568e-001,1.317841e+000,,,,,,,,,,,,,,64,2,3.000000e+000,1.804352e-002,0.000000e+000,0,,0,
1467268285.294,,-1.004844e+004,7.699034e+001,-2.121938e-003,5.784655e-005,3,9.614437e-001,2.726119e+000,,,,,,,,,,,,,,64,2,3.000000e+000,1.000977e-002,0.000000e+000,0,,0,
1467268343.364,,-8.039935e+003,7.699185e+001,-1.915952e-003,2.376020e-005,3,9.630653e-001,1.240125e+000,,,,,,,,,,,,,,64,2,3.000000e+000,1.604462e-002,0.000000e+000,0,,0,
1467268467.335,,-6.025503e+003,7.698985e+001,-1.784608e-003,4.674514e-005,3,9.867722e-001,2.619350e+000,,,,,,,,,,,,,,64,2,3.000000e+000,8.010864e-003,0.000000e+000,0,,0,
1467268525.576,,-4.017372e+003,7.699586e+001,-1.748338e-003,1.362227e-004,3,9.495043e-001,7.791556e+000,,,,,,,,,,,,,,64,2,3.000000e+000,8.026123e-003,0.000000e+000,0,,0,
1467268583.107,,-2.009094e+003,7.699336e+001,-1.731538e-003,2.002718e-004,3,9.419653e-001,1.156612e+001,,,,,,,,,,,,,,64,2,3.000000e+000,2.004242e-002,0.000000e+000,0,,0,
1467268683.578,,-4.892998e-001,7.699535e+001,-3.773921e-003,1.941867e-005,3,9.912729e-001,5.145488e-001,,,,,,,,,,,,,,64,2,3.000000e+000,1.998901e-003,0.000000e+000,0,,0,
1467268770.678,,2.009168e+003,7.698885e+001,-1.188284e-003,4.525740e-005,3,9.781865e-001,3.808634e+000,,,,,,,,,,,,,,64,2,3.000000e+000,2.001953e-002,0.000000e+000,0,,0,
1467268850.279,,4.017299e+003,7.699185e+001,-6.410799e-004,4.543245e-005,3,9.482919e-001,7.086863e+000,,,,,,,,,,,,,,64,2,3.000000e+000,1.402283e-002,0.000000e+000,0,,0,
1467268972.350,,6.025354e+003,7.699185e+001,-1.448444e-004,2.971035e-005,3,7.361395e-001,2.051191e+001,,,,,,,,,,,,,,64,2,3.000000e+000,8.010864e-003,0.000000e+000,0,,0,
1467269074.852,,8.038749e+003,7.698935e+001,4.848542e-004,2.992702e-004,3,7.538923e-001,6.172375e+001,,,,,,,,,,,,,,64,2,3.000000e+000,1.200867e-002,0.000000e+000,0,,0,
1467269133.172,,1.004547e+004,7.698685e+001,8.134190e-004,4.410663e-004,3,8.425444e-001,5.422375e+001,,,,,,,,,,,,,,64,2,3.000000e+000,5.007935e-002,0.000000e+000,0,,0,