File: SP-M4-239-3-0104-#4/Irradiated/Tc SPM4-239-3-0104-#4-1Cu.txt
[Header]
TITLE,MPMS DC Measurement
BYAPP,MPMS Measurement,2.1,Summary
FILEOPENTIME, 1467279666.602000 6/30/2016, 4:41:06 AM

INFO, APPNAME, MPMS MultiVu Application, Revision 1.60,  Build 081

INFO, NAME, tb11c
INFO, WEIGHT, 0.100
INFO, AREA, 1.000
INFO, LENGTH, 1.000
INFO, SHAPE, 1
INFO, COMMENT, 650C in 0.1% O2 in AR, single xtal, H//ab, lN2 quench
INFO, SEQUENCE FILE: Sequence_MT_5_27_77_45.seq


INFO, BACKGROUND DATA FILE:, None


STARTUPAXIS,X,4,LINEAR,AUTO,0.000000,0.000000
STARTUPAXIS,Y1,5,LINEAR,AUTO,0.000000,0.000000


STARTUPGROUP,Longitudinal
FIELDGROUP,Longitudinal,1,2,3,4,5,6,7,8,9,15,16,17,18,27,28
FIELDGROUP,Transverse,1,2,3,4,10,11,12,13,14,19,20,21,22,27,28

PLOT_APPEARANCE,ALL,HORZ_GRID_ON,VERT_GRID_ON,MARKERS_AND_LINES

[Data]
Time,Comment,Field (Oe),Temperature (K),Long Moment (emu),Long Scan Std Dev,Long Algorithm,Long Reg Fit,Long Percent Error (%),Trans Moment (emu),Trans Scan Std Dev,Trans Algorithm,Trans Reg Fit,Trans Percent Error (%),Long Moment [w/o ABS] (emu),Long Scan Std Dev [w/o ABS],Long Reg Fit [w/o ABS],Long Percent Error [w/o ABS] (%),Trans Moment [w/o ABS] (emu),Trans Scan Std Dev [w/o ABS],Trans Reg Fit [w/o ABS],Trans Percent Error [w/o ABS] (%),Points per Scan,Scans per Measurement,Scan Length (cm),Delta Temp (K),Rot Position (deg),Error,EC Comp. Running,Using ABS,
1467279666.602,,2.000000e+001,7.498814e+001,-1.918704e-003,5.646196e-007,3,9.945130e-001,2.942713e-002,,,,,,,,,,,,,,64,2,3.000000e+000,7.637024e-003,0.000000e+000,0,,0,
1467279755.913,,2.000000e+001,7.537276e+001,-1.913287e-003,1.181593e-006,3,9.944307e-001,6.175724e-002,,,,,,,,,,,,,,64,2,3.000000e+000,3.487701e-001,0.000000e+000,0,,0,
1467279798.674,,2.000000e+001,7.577692e+001,-1.902388e-003,6.363680e-006,3,9.945101e-001,3.345101e-001,,,,,,,,,,,,,,64,2,3.000000e+000,3.813705e-001,0.000000e+000,0,,0,
1467279841.764,,2.000000e+001,7.617178e+001,-1.880683e-003,8.603225e-006,3,9.944576e-001,4.574522e-001,,,,,,,,,,,,,,64,2,3.000000e+000,3.671646e-001,0.000000e+000,0,,0,
1467279884.485,,2.000000e+001,7.653181e+001,-1.855285e-003,9.023130e-006,3,9.943733e-001,4.863474e-001,,,,,,,,,,,,,,64,2,3.000000e+000,3.526764e-001,0.000000e+000,0,,0,
1467279927.945,,2.000000e+001,7.688700e+001,-1.828750e-003,9.844829e-006,3,9.943024e-001,5.383364e-001,,,,,,,,,,,,,,64,2,3.000000e+000,3.636627e-001,0.000000e+000,0,,0,
1467279970.695,,2.000000e+001,7.724322e+001,-1.799913e-003,1.052264e-005,3,9.942272e-001,5.846192e-001,,,,,,,,,,,,,,64,2,3.000000e+000,3.486633e-001,0.000000e+000,0,,0,
1467280013.306,,2.000000e+001,7.759589e+001,-1.768525e-003,1.195695e-005,3,9.941310e-001,6.760969e-001,,,,,,,,,,,,,,64,2,3.000000e+000,3.313141e-001,0.000000e+000,0,,0,
1467280055.436,,2.000000e+001,7.794438e+001,-1.733690e-003,1.284145e-005,3,9.940474e-001,7.407005e-001,,,,,,,,,,,,,,64,2,3.000000e+000,3.423004e-001,0.000000e+000,0,,0,
1467280097.877,,2.000000e+001,7.830115e+001,-1.693777e-003,1.467534e-005,3,9.939250e-001,8.664265e-001,,,,,,,,,,,,,,64,2,3.000000e+000,3.219986e-001,0.000000e+000,0,,0,
1467280141.097,,2.000000e+001,7.865326e+001,-1.649078e-003,1.675214e-005,3,9.938128e-001,1.015849e+000,,,,,,,,,,,,,,64,2,3.000000e+000,3.415833e-001,0.000000e+000,0,,0,
1467280183.898,,2.000000e+001,7.899514e+001,-1.598785e-003,1.873147e-005,3,9.936675e-001,1.171607e+000,,,,,,,,,,,,,,64,2,3.000000e+000,3.316727e-001,0.000000e+000,0,,0,
1467280226.578,,2.000000e+001,7.935612e+001,-1.542291e-003,1.990895e-005,3,9.935223e-001,1.290869e+000,,,,,,,,,,,,,,64,2,3.000000e+000,3.343658e-001,0.000000e+000,0,,0,
1467280269.698,,2.000000e+001,7.970141e+001,-1.479265e-003,2.358536e-005,3,9.933119e-001,1.594397e+000,,,,,,,,,,,,,,64,2,3.000000e+000,3.455658e-001,0.000000e+000,0,,0,
1467280312.759,,2.000000e+001,8.005423e+001,-1.407617e-003,2.717657e-005,3,9.930574e-001,1.930680e+000,,,,,,,,,,,,,,64,2,3.000000e+000,3.483353e-001,0.000000e+000,0,,0,
1467280356.089,,2.000000e+001,8.040118e+001,-1.330131e-003,2.875633e-005,3,9.927302e-001,2.161917e+000,,,,,,,,,,,,,,64,2,3.000000e+000,3.163376e-001,0.000000e+000,0,,0,
1467280397.400,,2.000000e+001,8.072739e+001,-1.248575e-003,2.911137e-005,3,9.923554e-001,2.331568e+000,,,,,,,,,,,,,,64,2,3.000000e+000,3.274536e-001,0.000000e+000,0,,0,
1467280440.890,,2.000000e+001,8.107635e+001,-1.157898e-003,3.473304e-005,3,9.918638e-001,2.999664e+000,,,,,,,,,,,,,,64,2,3.000000e+000,3.475189e-001,0.000000e+000,0,,0,
1467280484.491,,2.000000e+001,8.143356e+001,-1.059822e-003,3.530745e-005,3,9.912003e-001,3.331452e+000,,,,,,,,,,,,,,64,2,3.000000e+000,3.458252e-001,0.000000e+000,0,,0,
1467280527.131,,2.000000e+001,8.176231e+001,-9.622864e-004,3.276016e-005,3,9.904011e-001,3.404409e+000,,,,,,,,,,,,,,64,2,3.000000e+000,3.104553e-001,0.000000e+000,0,,0,
1467280570.711,,2.000000e+001,8.211938e+001,-8.645081e-004,3.502136e-005,3,9.894559e-001,4.051015e+000,,,,,,,,,,,,,,64,2,3.000000e+000,3.376236e-001,0.000000e+000,0,,0,
1467280634.932,,2.000000e+001,8.264632e+001,-7.173705e-004,3.428193e-005,3,9.874959e-001,4.778832e+000,,,,,,,,,,,,,,64,2,3.000000e+000,3.461075e-001,0.000000e+000,0,,0,
1467280678.063,,2.000000e+001,8.300235e+001,-6.209699e-004,3.405572e-005,3,9.857649e-001,5.484280e+000,,,,,,,,,,,,,,64,2,3.000000e+000,3.579941e-001,0.000000e+000,0,,0,
1467280720.683,,2.000000e+001,8.337035e+001,-5.254493e-004,3.180470e-005,3,9.833083e-001,6.052857e+000,,,,,,,,,,,,,,64,2,3.000000e+000,3.122559e-001,0.000000e+000,0,,0,
1467280763.433,,2.000000e+001,8.369182e+001,-4.409768e-004,2.867136e-005,3,9.802448e-001,6.501785e+000,,,,,,,,,,,,,,64,2,3.000000e+000,2.958984e-001,0.000000e+000,0,,0,
1467280849.484,,2.000000e+001,8.436281e+001,-2.991507e-004,2.233468e-005,3,9.719914e-001,7.466030e+000,,,,,,,,,,,,,,64,2,3.000000e+000,3.284683e-001,0.000000e+000,0,,0,
1467280892.925,,2.000000e+001,8.470496e+001,-2.382893e-004,2.133876e-005,3,9.651360e-001,8.954980e+000,,,,,,,,,,,,,,64,2,3.000000e+000,3.522797e-001,0.000000e+000,0,,0,
1467280957.445,,2.000000e+001,8.524303e+001,-1.555090e-004,1.723022e-005,3,9.473158e-001,1.107988e+001,,,,,,,,,,,,,,64,2,3.000000e+000,3.611908e-001,0.000000e+000,0,,0,
1467281042.416,,2.000000e+001,8.591472e+001,-7.285223e-005,1.232253e-005,3,8.925138e-001,1.691441e+001,,,,,,,,,,,,,,64,2,3.000000e+000,3.492203e-001,0.000000e+000,0,,0,
1467281086.067,,2.000000e+001,8.625907e+001,-4.171969e-005,8.997686e-006,3,8.198903e-001,2.156700e+001,,,,,,,,,,,,,,64,2,3.000000e+000,3.394394e-001,0.000000e+000,0,,0,
1467281172.787,,2.000000e+001,8.693789e+001,-6.222195e-006,3.693513e-006,3,1.523269e-001,5.936028e+001,,,,,,,,,,,,,,64,2,3.000000e+000,3.318710e-001,0.000000e+000,0,,0,
1467281215.898,,2.000000e+001,8.729475e+001,1.677186e-006,4.189752e-006,3,7.237008e-002,2.498085e+002,,,,,,,,,,,,,,64,2,3.000000e+000,3.192291e-001,0.000000e+000,0,,0,
1467281257.748,,2.000000e+001,8.764546e+001,5.781112e-006,1.816901e-007,3,5.163314e-001,3.142823e+000,,,,,,,,,,,,,,64,2,3.000000e+000,3.544617e-001,0.000000e+000,0,,0,
1467281300.589,,2.000000e+001,8.801272e+001,5.122629e-006,6.201621e-007,3,7.353010e-001,1.210633e+001,,,,,,,,,,,,,,64,2,3.000000e+000,3.469543e-001,0.000000e+000,0,,0,
1467281342.669,,2.000000e+001,8.836052e+001,3.708507e-006,3.389777e-007,3,8.796223e-001,9.140544e+000,,,,,,,,,,,,,,64,2,3.000000e+000,3.385773e-001,0.000000e+000,0,,0,
1467281386.050,,2.000000e+001,8.871040e+001,3.193566e-006,4.842730e-008,3,9.535985e-001,1.516402e+000,,,,,,,,,,,,,,64,2,3.000000e+000,3.441544e-001,0.000000e+000,0,,0,
1467281428.630,,2.000000e+001,8.906613e+001,3.150079e-006,9.895532e-009,3,9.626801e-001,3.141360e-001,,,,,,,,,,,,,,64,2,3.000000e+000,3.152847e-001,0.000000e+000,0,,0,
1467281471.250,,2.000000e+001,8.940147e+001,3.157829e-006,2.587553e-008,3,9.676377e-001,8.194087e-001,,,,,,,,,,,,,,64,2,3.000000e+000,3.174973e-001,0.000000e+000,0,,0,
1467281513.961,,2.000000e+001,8.973579e+001,3.193691e-006,1.058189e-008,3,9.660277e-001,3.313374e-001,,,,,,,,,,,,,,64,2,3.000000e+000,3.116608e-001,0.000000e+000,0,,0,
1467281556.931,,2.000000e+001,9.008897e+001,3.190675e-006,1.635637e-008,3,9.664401e-001,5.126306e-001,,,,,,,,,,,,,,64,2,3.000000e+000,3.191299e-001,0.000000e+000,0,,0,
1467281600.712,,2.000000e+001,9.042590e+001,3.175609e-006,9.465452e-009,3,9.671263e-001,2.980673e-001,,,,,,,,,,,,,,64,2,3.000000e+000,3.373642e-001,0.000000e+000,0,,0,
1467281643.162,,2.000000e+001,9.077717e+001,3.189433e-006,3.512988e-010,3,9.673744e-001,1.101446e-002,,,,,,,,,,,,,,64,2,3.000000e+000,2.857742e-001,0.000000e+000,0,,0,
1467281685.963,,2.000000e+001,9.109366e+001,3.182093e-006,1.367075e-008,3,9.659196e-001,4.296149e-001,,,,,,,,,,,,,,64,2,3.000000e+000,3.363800e-001,0.000000e+000,0,,0,
1467281729.433,,2.000000e+001,9.142780e+001,3.168638e-006,1.625332e-008,3,9.672021e-001,5.129433e-001,,,,,,,,,,,,,,64,2,3.000000e+000,3.413925e-001,0.000000e+000,0,,0,
1467281771.583,,2.000000e+001,9.177373e+001,3.172515e-006,1.257280e-009,3,9.655265e-001,3.963039e-002,,,,,,,,,,,,,,64,2,3.000000e+000,3.106766e-001,0.000000e+000,0,,0,
1467281815.014,,2.000000e+001,9.210892e+001,3.170607e-006,1.715496e-008,3,9.640903e-001,5.410621e-001,,,,,,,,,,,,,,64,2,3.000000e+000,3.459091e-001,0.000000e+000,0,,0,
1467281857.354,,2.000000e+001,9.246854e+001,3.169689e-006,2.984030e-010,3,9.649540e-001,9.414266e-003,,,,,,,,,,,,,,64,2,3.000000e+000,3.233490e-001,0.000000e+000,0,,0,
1467281900.495,,2.000000e+001,9.282514e+001,3.156844e-006,4.784898e-009,3,9.659245e-001,1.515722e-001,,,,,,,,,,,,,,64,2,3.000000e+000,3.647995e-001,0.000000e+000,0,,0,
1467281943.535,,2.000000e+001,9.318273e+001,3.146986e-006,3.802870e-009,3,9.655471e-001,1.208417e-001,,,,,,,,,,,,,,64,2,3.000000e+000,3.277664e-001,0.000000e+000,0,,0,
1467281986.956,,2.000000e+001,9.355708e+001,3.154108e-006,2.461342e-009,3,9.674702e-001,7.803608e-002,,,,,,,,,,,,,,64,2,3.000000e+000,3.358231e-001,0.000000e+000,0,,0,
1467282029.946,,2.000000e+001,9.390046e+001,3.125885e-006,1.733020e-008,3,9.648823e-001,5.544094e-001,,,,,,,,,,,,,,64,2,3.000000e+000,3.438263e-001,0.000000e+000,0,,0,
1467282072.056,,2.000000e+001,9.424609e+001,3.134508e-006,5.173176e-009,3,9.656618e-001,1.650394e-001,,,,,,,,,,,,,,64,2,3.000000e+000,3.402939e-001,0.000000e+000,0,,0,
1467282114.667,,2.000000e+001,9.460638e+001,3.129186e-006,7.065205e-009,3,9.658931e-001,2.257841e-001,,,,,,,,,,,,,,64,2,3.000000e+000,3.541794e-001,0.000000e+000,0,,0,
1467282306.199,,2.000000e+001,9.500920e+001,3.146955e-006,1.981759e-008,3,9.659448e-001,6.297386e-001,,,,,,,,,,,,,,64,2,3.000000e+000,2.047729e-002,0.000000e+000,0,,0,
1467282349.119,,2.000000e+001,9.498654e+001,3.125632e-006,1.514508e-008,3,9.657871e-001,4.845444e-001,,,,,,,,,,,,,,64,2,3.000000e+000,1.461029e-002,0.000000e+000,0,,0,
1467282391.620,,2.000000e+001,9.498946e+001,3.144112e-006,1.229417e-008,3,9.655656e-001,3.910220e-001,,,,,,,,,,,,,,64,2,3.000000e+000,1.461029e-002,0.000000e+000,0,,0,
1467282434.150,,2.000000e+001,9.498580e+001,3.133613e-006,1.088962e-008,3,9.624853e-001,3.475101e-001,,,,,,,,,,,,,,64,2,3.000000e+000,2.924347e-002,0.000000e+000,0,,0,
1467282477.101,,2.000000e+001,9.499385e+001,3.150443e-006,2.329087e-008,3,9.652719e-001,7.392885e-001,,,,,,,,,,,,,,64,2,3.000000e+000,3.801727e-002,0.000000e+000,0,,0,
1467282519.441,,2.000000e+001,9.498873e+001,3.153748e-006,6.572422e-009,3,9.671587e-001,2.084004e-001,,,,,,,,,,,,,,64,2,3.000000e+000,1.169586e-002,0.000000e+000,0,,0,
1467282562.061,,2.000000e+001,9.498581e+001,3.158470e-006,1.750802e-008,3,9.667712e-001,5.543197e-001,,,,,,,,,,,,,,64,2,3.000000e+000,2.046967e-002,0.000000e+000,0,,0,
1467282604.402,,2.000000e+001,9.499239e+001,3.145864e-006,2.249277e-009,3,9.690398e-001,7.149950e-002,,,,,,,,,,,,,,64,2,3.000000e+000,4.094696e-002,0.000000e+000,0,,0,
1467282646.022,,2.000000e+001,9.498141e+001,3.143791e-006,7.653811e-009,3,9.670806e-001,2.434580e-001,,,,,,,,,,,,,,64,2,3.000000e+000,2.046967e-002,0.000000e+000,0,,0,
1467282688.903,,2.000000e+001,9.499678e+001,3.149018e-006,3.958663e-009,3,9.660183e-001,1.257110e-001,,,,,,,,,,,,,,64,2,3.000000e+000,2.339935e-002,0.000000e+000,0,,0,
1467282730.863,,2.000000e+001,9.499165e+001,3.157619e-006,1.026339e-008,3,9.682437e-001,3.250357e-001,,,,,,,,,,,,,,64,2,3.000000e+000,4.094696e-002,0.000000e+000,0,,0,
1467282773.073,,2.000000e+001,9.499603e+001,3.161064e-006,1.528833e-009,3,9.660434e-001,4.836451e-002,,,,,,,,,,,,,,64,2,3.000000e+000,1.461792e-002,0.000000e+000,0,,0,
1467282815.684,,2.000000e+001,9.499532e+001,3.165792e-006,7.214889e-009,3,9.662903e-001,2.279015e-001,,,,,,,,,,,,,,64,2,3.000000e+000,2.633667e-002,0.000000e+000,0,,0,
1467282857.564,,2.000000e+001,9.499239e+001,3.155257e-006,6.627247e-009,3,9.649031e-001,2.100383e-001,,,,,,,,,,,,,,64,2,3.000000e+000,8.773804e-003,0.000000e+000,0,,0,
1467282900.445,,2.000000e+001,9.497776e+001,3.158084e-006,6.469525e-009,3,9.639069e-001,2.048560e-001,,,,,,,,,,,,,,64,2,3.000000e+000,2.339172e-002,0.000000e+000,0,,0,
1467282942.805,,2.000000e+001,9.497191e+001,3.161367e-006,9.124282e-009,3,9.674844e-001,2.886183e-001,,,,,,,,,,,,,,64,2,3.000000e+000,2.922058e-003,0.000000e+000,0,,0,
1467282985.016,,2.000000e+001,9.498872e+001,3.163914e-006,2.120639e-008,3,9.676924e-001,6.702580e-001,,,,,,,,,,,,,,64,2,3.000000e+000,1.462555e-002,0.000000e+000,0,,0,
1467283027.526,,2.000000e+001,9.498581e+001,3.157895e-006,5.614832e-009,3,9.657805e-001,1.778030e-001,,,,,,,,,,,,,,64,2,3.000000e+000,2.046967e-002,0.000000e+000,0,,0,
1467283090.767,,2.000000e+001,9.499165e+001,3.169407e-006,4.815446e-009,3,9.669890e-001,1.519352e-001,,,,,,,,,,,,,,64,2,3.000000e+000,8.773804e-003,0.000000e+000,0,,0,
1467283133.307,,2.000000e+001,9.499165e+001,3.143887e-006,2.545525e-008,3,9.665645e-001,8.096746e-001,,,,,,,,,,,,,,64,2,3.000000e+000,1.169586e-002,0.000000e+000,0,,0,
1467283175.198,,2.000000e+001,9.499384e+001,3.180822e-006,4.210424e-008,3,9.678783e-001,1.323691e+000,,,,,,,,,,,,,,64,2,3.000000e+000,1.168823e-002,0.000000e+000,0,,0,
1467283217.108,,2.000000e+001,9.498727e+001,3.129410e-006,1.662664e-008,3,9.662392e-001,5.313028e-001,,,,,,,,,,,,,,64,2,3.000000e+000,1.169586e-002,0.000000e+000,0,,0,
1467283259.898,,2.000000e+001,9.499165e+001,3.158187e-006,7.965559e-009,3,9.643822e-001,2.522193e-001,,,,,,,,,,,,,,64,2,3.000000e+000,1.461029e-002,0.000000e+000,0,,0,
1467283302.099,,2.000000e+001,9.499092e+001,3.154360e-006,3.035479e-009,3,9.668040e-001,9.623120e-002,,,,,,,,,,,,,,64,2,3.000000e+000,5.844116e-003,0.000000e+000,0,,0,
1467283345.119,,2.000000e+001,9.499458e+001,3.173546e-006,1.297474e-008,3,9.666594e-001,4.088405e-001,,,,,,,,,,,,,,64,2,3.000000e+000,8.766174e-003,0.000000e+000,0,,0,
1467283387.050,,2.000000e+001,9.499384e+001,3.160587e-006,8.127944e-009,3,9.667007e-001,2.571656e-001,,,,,,,,,,,,,,64,2,3.000000e+000,1.754761e-002,0.000000e+000,0,,0,
1467283429.000,,2.000000e+001,9.498508e+001,3.159183e-006,2.045411e-009,3,9.658451e-001,6.474493e-002,,,,,,,,,,,,,,64,2,3.000000e+000,3.802490e-002,0.000000e+000,0,,0,
1467283470.630,,2.000000e+001,9.497996e+001,3.165307e-006,1.515971e-009,3,9.661875e-001,4.789332e-002,,,,,,,,,,,,,,64,2,3.000000e+000,2.046967e-002,0.000000e+000,0,,0,
1467283513.651,,2.000000e+001,9.499238e+001,3.189124e-006,5.504442e-008,3,9.668607e-001,1.726004e+000,,,,,,,,,,,,,,64,2,3.000000e+000,1.753998e-002,0.000000e+000,0,,0,
1467283555.671,,2.000000e+001,9.497849e+001,3.126440e-006,5.814919e-008,3,9.648138e-001,1.859917e+000,,,,,,,,,,,,,,64,2,3.000000e+000,1.462555e-002,0.000000e+000,0,,0,
1467283598.592,,2.000000e+001,9.498873e+001,3.183363e-006,5.440291e-008,3,9.651949e-001,1.708976e+000,,,,,,,,,,,,,,64,2,3.000000e+000,1.461029e-002,0.000000e+000,0,,0,
1467283640.592,,2.000000e+001,9.498946e+001,3.149475e-006,2.623502e-008,3,9.650495e-001,8.329967e-001,,,,,,,,,,,,,,64,2,3.000000e+000,2.338409e-002,0.000000e+000,0,,0,
1467283682.873,,2.000000e+001,9.498288e+001,3.178368e-006,5.820450e-008,3,9.668630e-001,1.831270e+000,,,,,,,,,,,,,,64,2,3.000000e+000,2.632141e-002,0.000000e+000,0,,0,
1467283725.903,,2.000000e+001,9.498581e+001,3.137454e-006,3.020816e-008,3,9.652891e-001,9.628240e-001,,,,,,,,,,,,,,64,2,3.000000e+000,8.773804e-003,0.000000e+000,0,,0,
1467283768.613,,2.000000e+001,9.500189e+001,3.176322e-006,3.218926e-009,3,9.666905e-001,1.013413e-001,,,,,,,,,,,,,,64,2,3.000000e+000,3.511047e-002,0.000000e+000,0,,0,
1467283811.254,,2.000000e+001,9.499092e+001,3.161769e-006,1.173804e-008,3,9.643610e-001,3.712492e-001,,,,,,,,,,,,,,64,2,3.000000e+000,2.631378e-002,0.000000e+000,0,,0,
1467283853.514,,2.000000e+001,9.499165e+001,3.169484e-006,1.560008e-008,3,9.644991e-001,4.921962e-001,,,,,,,,,,,,,,64,2,3.000000e+000,2.046967e-002,0.000000e+000,0,,0,
1467283895.615,,2.000000e+001,9.498946e+001,3.169770e-006,1.754243e-009,3,9.670839e-001,5.534292e-002,,,,,,,,,,,,,,64,2,3.000000e+000,2.924347e-002,0.000000e+000,0,,0,
1467283938.985,,2.000000e+001,9.498215e+001,3.170060e-006,8.970900e-009,3,9.668050e-001,2.829883e-001,,,,,,,,,,,,,,64,2,3.000000e+000,2.339935e-002,0.000000e+000,0,,0,
1467283981.306,,2.000000e+001,9.498508e+001,3.176887e-006,1.328906e-008,3,9.656905e-001,4.183045e-001,,,,,,,,,,,,,,64,2,3.000000e+000,5.851746e-003,0.000000e+000,0,,0,
1467284023.926,,2.000000e+001,9.499019e+001,3.172565e-006,1.205268e-008,3,9.662857e-001,3.799033e-001,,,,,,,,,,,,,,64,2,3.000000e+000,1.461029e-002,0.000000e+000,0,,0,
1467284066.076,,2.000000e+001,9.498873e+001,3.165632e-006,1.235736e-008,3,9.672536e-001,3.903599e-001,,,,,,,,,,,,,,64,2,3.000000e+000,1.169586e-002,0.000000e+000,0,,0,
1467284107.527,,2.000000e+001,9.498946e+001,3.167788e-006,5.151310e-010,3,9.666255e-001,1.626154e-002,,,,,,,,,,,,,,64,2,3.000000e+000,2.922058e-003,0.000000e+000,0,,0,
1467284150.277,,2.000000e+001,9.498946e+001,3.169666e-006,8.222321e-009,3,9.662483e-001,2.594065e-001,,,,,,,,,,,,,,64,2,3.000000e+000,5.844116e-003,0.000000e+000,0,,0,
1467284192.388,,2.000000e+001,9.498727e+001,3.162434e-006,1.339807e-008,3,9.668704e-001,4.236633e-001,,,,,,,,,,,,,,64,2,3.000000e+000,1.169586e-002,0.000000e+000,0,,0,
1467284234.568,,2.000000e+001,9.499019e+001,3.170842e-006,2.007468e-009,3,9.676991e-001,6.331024e-002,,,,,,,,,,,,,,64,2,3.000000e+000,2.922058e-003,0.000000e+000,0,,0,
1467284277.109,,2.000000e+001,9.499385e+001,3.174354e-006,3.294973e-009,3,9.683653e-001,1.037998e-001,,,,,,,,,,,,,,64,2,3.000000e+000,5.851746e-003,0.000000e+000,0,,0,
1467284319.019,,2.000000e+001,9.499092e+001,3.169072e-006,1.059025e-008,3,9.680834e-001,3.341751e-001,,,,,,,,,,,,,,64,2,3.000000e+000,1.169586e-002,0.000000e+000,0,,0,