File: SP-M4-239-3-0104-#4/Pristine/MH77K SPM4-239-3-0104-#4-BL.txt
[Header]
TITLE,MPMS DC Measurement
BYAPP,MPMS Measurement,2.1,Summary
FILEOPENTIME, 1454899650.424000 2/7/2016, 8:47:30 PM

INFO, APPNAME, MPMS MultiVu Application, Revision 1.60,  Build 081

INFO, NAME, tb11c
INFO, WEIGHT, 0.100
INFO, AREA, 1.000
INFO, LENGTH, 1.000
INFO, SHAPE, 1
INFO, COMMENT, 650C in 0.1% O2 in AR, single xtal, H//ab, lN2 quench
INFO, SEQUENCE FILE: Sequence_MT_5_27_77_45.seq


INFO, BACKGROUND DATA FILE:, None


STARTUPAXIS,X,4,LINEAR,AUTO,0.000000,0.000000
STARTUPAXIS,Y1,5,LINEAR,AUTO,0.000000,0.000000


STARTUPGROUP,Longitudinal
FIELDGROUP,Longitudinal,1,2,3,4,5,6,7,8,9,15,16,17,18,27,28
FIELDGROUP,Transverse,1,2,3,4,10,11,12,13,14,19,20,21,22,27,28

PLOT_APPEARANCE,ALL,HORZ_GRID_ON,VERT_GRID_ON,MARKERS_AND_LINES

[Data]
Time,Comment,Field (Oe),Temperature (K),Long Moment (emu),Long Scan Std Dev,Long Algorithm,Long Reg Fit,Long Percent Error (%),Trans Moment (emu),Trans Scan Std Dev,Trans Algorithm,Trans Reg Fit,Trans Percent Error (%),Long Moment [w/o ABS] (emu),Long Scan Std Dev [w/o ABS],Long Reg Fit [w/o ABS],Long Percent Error [w/o ABS] (%),Trans Moment [w/o ABS] (emu),Trans Scan Std Dev [w/o ABS],Trans Reg Fit [w/o ABS],Trans Percent Error [w/o ABS] (%),Points per Scan,Scans per Measurement,Scan Length (cm),Delta Temp (K),Rot Position (deg),Error,EC Comp. Running,Using ABS,
1454899650.424,,1.000000e+003,7.698606e+001,-5.884808e-003,5.239611e-005,3,9.981101e-001,8.903623e-001,,,,,,,,,,,,,,64,2,3.000000e+000,2.202606e-002,0.000000e+000,0,,0,
1454899704.085,,2.009168e+003,7.700309e+001,-5.106567e-003,9.814585e-005,3,9.930623e-001,1.921953e+000,,,,,,,,,,,,,,64,2,3.000000e+000,1.003265e-002,0.000000e+000,0,,0,
1454899756.726,,3.013196e+003,7.699658e+001,-4.402636e-003,9.092096e-005,3,9.764967e-001,2.065149e+000,,,,,,,,,,,,,,64,2,3.000000e+000,2.004242e-002,0.000000e+000,0,,0,
1454899830.906,,4.017818e+003,7.699507e+001,-3.957427e-003,8.282959e-005,3,9.942659e-001,2.093016e+000,,,,,,,,,,,,,,64,2,3.000000e+000,1.203918e-002,0.000000e+000,0,,0,
1454899884.485,,5.021994e+003,7.699908e+001,-3.378728e-003,2.836285e-004,3,9.490719e-001,8.394535e+000,,,,,,,,,,,,,,64,2,3.000000e+000,1.604462e-002,0.000000e+000,0,,0,
1454899938.055,,6.026244e+003,7.700159e+001,-3.046973e-003,2.254935e-004,3,9.400735e-001,7.400576e+000,,,,,,,,,,,,,,64,2,3.000000e+000,1.603699e-002,0.000000e+000,0,,0,
1454899992.554,,7.030050e+003,7.699758e+001,-2.652699e-003,2.344348e-004,3,9.497081e-001,8.837595e+000,,,,,,,,,,,,,,64,2,3.000000e+000,1.403046e-002,0.000000e+000,0,,0,
1454900090.094,,8.040232e+003,7.699557e+001,-2.187870e-003,2.626353e-004,3,9.283499e-001,1.200416e+001,,,,,,,,,,,,,,64,2,3.000000e+000,1.602173e-002,0.000000e+000,0,,0,
1454900207.255,,9.041962e+003,7.698506e+001,-1.266055e-003,3.244204e-005,3,9.698551e-001,2.562451e+000,,,,,,,,,,,,,,64,2,3.000000e+000,2.001953e-002,0.000000e+000,0,,0,
1454900261.915,,1.004814e+004,7.698355e+001,-2.420224e-003,1.297349e-003,3,9.150933e-001,5.360448e+001,,,,,,,,,,,,,,64,2,3.000000e+000,3.407288e-002,0.000000e+000,0,,0,
1454900373.899,,1.506836e+004,7.699757e+001,8.431625e-004,3.188655e-004,3,8.842945e-001,3.781779e+001,,,,,,,,,,,,,,64,2,3.000000e+000,6.011963e-003,0.000000e+000,0,,0,
1454900490.221,,2.008798e+004,7.699608e+001,7.825182e-004,5.317941e-003,3,4.740193e-001,6.795933e+002,,,,,,,,,,,,,,64,2,3.000000e+000,2.003479e-002,0.000000e+000,0,,0,
1454900561.872,,2.511071e+004,7.699708e+001,2.205762e-003,2.609993e-005,3,8.527119e-001,1.183262e+000,,,,,,,,,,,,,,64,2,3.000000e+000,1.603699e-002,0.000000e+000,0,,0,
1454900632.764,,3.012678e+004,7.698857e+001,4.256750e-003,8.757126e-004,3,6.245540e-001,2.057233e+001,,,,,,,,,,,,,,64,2,3.000000e+000,2.203369e-002,0.000000e+000,0,,0,
1454900705.655,,3.515100e+004,7.699256e+001,6.838337e-003,9.205497e-004,3,7.650937e-001,1.346160e+001,,,,,,,,,,,,,,64,2,3.000000e+000,6.011963e-003,0.000000e+000,0,,0,
1454900776.707,,4.017077e+004,7.699407e+001,5.000034e-003,3.388966e-003,3,6.821340e-001,6.777885e+001,,,,,,,,,,,,,,64,2,3.000000e+000,1.403809e-002,0.000000e+000,0,,0,
1454900847.318,,4.519054e+004,7.699657e+001,6.387756e-003,4.161804e-005,3,8.168663e-001,6.515283e-001,,,,,,,,,,,,,,64,2,3.000000e+000,1.202393e-002,0.000000e+000,0,,0,
1454900917.679,,5.021105e+004,7.699207e+001,6.642427e-003,3.146045e-004,3,9.031601e-001,4.736289e+000,,,,,,,,,,,,,,64,2,3.000000e+000,3.405762e-002,0.000000e+000,0,,0,
1454900988.041,,5.523452e+004,7.700209e+001,7.404663e-003,1.889032e-003,3,9.367712e-001,2.551138e+001,,,,,,,,,,,,,,64,2,3.000000e+000,2.604675e-002,0.000000e+000,0,,0,
1454901058.472,,6.025058e+004,7.699758e+001,8.857384e-003,1.215202e-003,3,9.413956e-001,1.371965e+001,,,,,,,,,,,,,,64,2,3.000000e+000,3.405762e-002,0.000000e+000,0,,0,
1454901171.675,,6.527258e+004,7.698706e+001,1.019301e-002,3.282515e-004,3,9.541302e-001,3.220360e+000,,,,,,,,,,,,,,64,2,3.000000e+000,1.000977e-002,0.000000e+000,0,,0,
1454901243.056,,7.029309e+004,7.699357e+001,9.855132e-003,1.260783e-004,3,9.438687e-001,1.279317e+000,,,,,,,,,,,,,,64,2,3.000000e+000,2.605438e-002,0.000000e+000,0,,0,
1454901356.570,,6.527258e+004,7.699157e+001,9.269746e-003,1.726328e-004,3,9.697970e-001,1.862325e+000,,,,,,,,,,,,,,64,2,3.000000e+000,2.404785e-002,0.000000e+000,0,,0,
1454901429.772,,6.025355e+004,7.699757e+001,9.105019e-003,1.366941e-005,3,9.695588e-001,1.501305e-001,,,,,,,,,,,,,,64,2,3.000000e+000,2.404785e-002,0.000000e+000,0,,0,
1454901503.253,,5.523156e+004,7.700159e+001,8.275168e-003,3.082074e-004,3,9.672715e-001,3.724485e+000,,,,,,,,,,,,,,64,2,3.000000e+000,2.604675e-002,0.000000e+000,0,,0,
1454901575.195,,5.021253e+004,7.699657e+001,8.929659e-003,7.488178e-004,3,9.397845e-001,8.385738e+000,,,,,,,,,,,,,,64,2,3.000000e+000,2.005005e-002,0.000000e+000,0,,0,
1454901646.716,,4.519202e+004,7.699207e+001,7.605841e-003,2.145577e-003,3,9.247230e-001,2.820960e+001,,,,,,,,,,,,,,64,2,3.000000e+000,8.010864e-003,0.000000e+000,0,,0,
1454901719.218,,4.017150e+004,7.700259e+001,6.139976e-003,8.602518e-004,3,9.767359e-001,1.401067e+001,,,,,,,,,,,,,,64,2,3.000000e+000,1.403046e-002,0.000000e+000,0,,0,
1454901792.969,,3.515025e+004,7.699208e+001,5.336792e-003,5.369295e-004,3,9.782640e-001,1.006090e+001,,,,,,,,,,,,,,64,2,3.000000e+000,2.404785e-002,0.000000e+000,0,,0,
1454901865.330,,3.012678e+004,7.699007e+001,3.821149e-003,3.773485e-004,3,8.388106e-001,9.875261e+000,,,,,,,,,,,,,,64,2,3.000000e+000,2.403259e-002,0.000000e+000,0,,0,
1454901937.471,,2.510923e+004,7.700058e+001,5.467945e-003,6.431741e-004,3,9.622496e-001,1.176263e+001,,,,,,,,,,,,,,64,2,3.000000e+000,1.805115e-002,0.000000e+000,0,,0,
1454902009.981,,2.008946e+004,7.699057e+001,5.104100e-003,5.389100e-005,3,9.765981e-001,1.055837e+000,,,,,,,,,,,,,,64,2,3.000000e+000,1.602173e-002,0.000000e+000,0,,0,
1454902082.652,,1.506806e+004,7.699306e+001,4.979598e-003,7.713522e-004,3,9.121550e-001,1.549025e+001,,,,,,,,,,,,,,64,2,3.000000e+000,8.010864e-003,0.000000e+000,0,,0,
1454902195.616,,1.004933e+004,7.699658e+001,5.371468e-003,8.007440e-005,3,9.868998e-001,1.490736e+000,,,,,,,,,,,,,,64,2,3.000000e+000,2.203369e-002,0.000000e+000,0,,0,
1454902254.607,,8.039194e+003,7.699959e+001,5.123907e-003,1.559368e-004,3,9.762412e-001,3.043318e+000,,,,,,,,,,,,,,64,2,3.000000e+000,3.406525e-002,0.000000e+000,0,,0,
1454902356.629,,6.026244e+003,7.699007e+001,5.322779e-003,1.101225e-004,3,9.798273e-001,2.068891e+000,,,,,,,,,,,,,,64,2,3.000000e+000,2.604675e-002,0.000000e+000,0,,0,
1454902414.790,,4.018188e+003,7.700058e+001,5.650022e-003,9.883107e-006,3,9.877601e-001,1.749216e-001,,,,,,,,,,,,,,64,2,3.000000e+000,2.204895e-002,0.000000e+000,0,,0,
1454902472.872,,2.009168e+003,7.699158e+001,5.942075e-003,2.821402e-005,3,9.900115e-001,4.748177e-001,,,,,,,,,,,,,,64,2,3.000000e+000,3.004456e-002,0.000000e+000,0,,0,
1454902532.523,,8.303267e-001,7.700459e+001,1.143511e-002,1.744609e-004,3,9.944900e-001,1.525660e+000,,,,,,,,,,,,,,64,2,3.000000e+000,4.005432e-003,0.000000e+000,0,,0,
1454902598.244,,-2.009687e+003,7.699658e+001,5.137412e-003,1.821534e-005,3,9.846948e-001,3.545626e-001,,,,,,,,,,,,,,64,2,3.000000e+000,2.404785e-002,0.000000e+000,0,,0,
1454902656.685,,-4.018188e+003,7.699658e+001,4.172992e-003,3.292130e-005,3,9.810878e-001,7.889135e-001,,,,,,,,,,,,,,64,2,3.000000e+000,2.204895e-002,0.000000e+000,0,,0,
1454902714.636,,-6.026541e+003,7.699658e+001,3.370264e-003,1.490698e-005,3,9.740697e-001,4.423090e-001,,,,,,,,,,,,,,64,2,3.000000e+000,4.809570e-002,0.000000e+000,0,,0,
1454902837.779,,-8.039342e+003,7.699007e+001,2.494373e-003,1.246645e-004,3,9.800996e-001,4.997828e+000,,,,,,,,,,,,,,64,2,3.000000e+000,8.010864e-003,0.000000e+000,0,,0,
1454902894.791,,-1.004784e+004,7.700108e+001,1.496571e-003,4.080678e-004,3,9.354013e-001,2.726686e+001,,,,,,,,,,,,,,64,2,3.000000e+000,2.404785e-002,0.000000e+000,0,,0,
1454903069.780,,-1.507013e+004,7.699406e+001,-3.400369e-003,7.202896e-005,3,9.374123e-001,2.118269e+000,,,,,,,,,,,,,,64,2,3.000000e+000,1.000977e-002,0.000000e+000,0,,0,
1454903184.264,,-2.009020e+004,7.700008e+001,-4.002132e-003,3.439522e-004,3,9.404999e-001,8.594223e+000,,,,,,,,,,,,,,64,2,3.000000e+000,1.403809e-002,0.000000e+000,0,,0,
1454903319.837,,-2.511146e+004,7.700008e+001,-4.315861e-003,6.396542e-005,3,9.537128e-001,1.482101e+000,,,,,,,,,,,,,,64,2,3.000000e+000,2.204895e-002,0.000000e+000,0,,0,
1454903391.048,,-3.013049e+004,7.698956e+001,-6.771115e-003,1.111504e-003,3,8.308906e-001,1.641538e+001,,,,,,,,,,,,,,64,2,3.000000e+000,1.802063e-002,0.000000e+000,0,,0,
1454903462.739,,-3.515396e+004,7.699106e+001,-5.976346e-003,6.005695e-005,3,9.592305e-001,1.004911e+000,,,,,,,,,,,,,,64,2,3.000000e+000,1.201630e-002,0.000000e+000,0,,0,
1454903532.991,,-4.017077e+004,7.699107e+001,-6.458148e-003,1.192275e-004,3,9.329568e-001,1.846156e+000,,,,,,,,,,,,,,64,2,3.000000e+000,1.000977e-002,0.000000e+000,0,,0,
1454903602.582,,-4.519499e+004,7.698956e+001,-8.108640e-003,2.578239e-003,3,7.684888e-001,3.179619e+001,,,,,,,,,,,,,,64,2,3.000000e+000,2.805328e-002,0.000000e+000,0,,0,
1454903673.794,,-5.021401e+004,7.699557e+001,-8.170646e-003,4.272512e-004,3,9.072695e-001,5.229099e+000,,,,,,,,,,,,,,64,2,3.000000e+000,2.604675e-002,0.000000e+000,0,,0,
1454903744.995,,-5.523156e+004,7.699608e+001,-7.535568e-003,4.548965e-004,3,9.143120e-001,6.036659e+000,,,,,,,,,,,,,,64,2,3.000000e+000,2.004242e-002,0.000000e+000,0,,0,
1454903816.556,,-6.025355e+004,7.699959e+001,-9.145271e-003,3.566104e-004,3,9.643607e-001,3.899397e+000,,,,,,,,,,,,,,64,2,3.000000e+000,3.807068e-002,0.000000e+000,0,,0,
1454903952.067,,-6.527852e+004,7.698857e+001,-9.781485e-003,4.788936e-006,3,9.609635e-001,4.895919e-002,,,,,,,,,,,,,,64,2,3.000000e+000,2.604675e-002,0.000000e+000,0,,0,
1454904021.957,,-7.029309e+004,7.698506e+001,-1.137063e-002,1.267856e-003,3,9.389290e-001,1.115028e+001,,,,,,,,,,,,,,64,2,3.000000e+000,2.804565e-002,0.000000e+000,0,,0,
1454904137.509,,-6.527111e+004,7.699557e+001,-9.613717e-003,2.955778e-004,3,9.187263e-001,3.074543e+000,,,,,,,,,,,,,,64,2,3.000000e+000,1.403809e-002,0.000000e+000,0,,0,
1454904211.150,,-6.025355e+004,7.700108e+001,-8.980483e-003,4.202877e-004,3,9.515501e-001,4.680013e+000,,,,,,,,,,,,,,64,2,3.000000e+000,4.020691e-003,0.000000e+000,0,,0,
1454904285.202,,-5.522859e+004,7.699307e+001,-8.273991e-003,1.370471e-004,3,9.543358e-001,1.656360e+000,,,,,,,,,,,,,,64,2,3.000000e+000,2.204895e-002,0.000000e+000,0,,0,
1454904358.733,,-5.020807e+004,7.699557e+001,-7.960364e-003,2.370958e-004,3,9.763262e-001,2.978454e+000,,,,,,,,,,,,,,64,2,3.000000e+000,1.803589e-002,0.000000e+000,0,,0,
1454904430.875,,-4.518461e+004,7.699156e+001,-7.003599e-003,3.739548e-004,3,9.703773e-001,5.339467e+000,,,,,,,,,,,,,,64,2,3.000000e+000,1.001740e-002,0.000000e+000,0,,0,
1454904503.666,,-4.016854e+004,7.699357e+001,-7.232125e-003,5.173536e-004,3,8.771557e-001,7.153549e+000,,,,,,,,,,,,,,64,2,3.000000e+000,2.603149e-002,0.000000e+000,0,,0,
1454904577.258,,-3.514803e+004,7.699057e+001,-5.647787e-003,5.648863e-005,3,9.478602e-001,1.000190e+000,,,,,,,,,,,,,,64,2,3.000000e+000,1.402283e-002,0.000000e+000,0,,0,
1454904692.100,,-3.012604e+004,7.699257e+001,-5.300160e-003,2.930046e-004,3,9.765795e-001,5.528222e+000,,,,,,,,,,,,,,64,2,3.000000e+000,4.013062e-003,0.000000e+000,0,,0,
1454904764.301,,-2.510701e+004,7.699106e+001,-5.445797e-003,4.426318e-004,3,9.853733e-001,8.127953e+000,,,,,,,,,,,,,,64,2,3.000000e+000,1.200867e-002,0.000000e+000,0,,0,
1454904835.973,,-2.008502e+004,7.699107e+001,-5.118328e-003,3.910763e-004,3,9.793189e-001,7.640704e+000,,,,,,,,,,,,,,64,2,3.000000e+000,2.003479e-002,0.000000e+000,0,,0,
1454904907.234,,-1.506954e+004,7.698606e+001,-4.896972e-003,3.845979e-004,3,9.885255e-001,7.853790e+000,,,,,,,,,,,,,,64,2,3.000000e+000,3.607178e-002,0.000000e+000,0,,0,
1454905020.245,,-1.005051e+004,7.699056e+001,-5.176867e-003,1.889674e-004,3,9.872493e-001,3.650227e+000,,,,,,,,,,,,,,64,2,3.000000e+000,1.802063e-002,0.000000e+000,0,,0,
1454905078.564,,-8.039342e+003,7.699757e+001,-5.249087e-003,1.158060e-004,3,9.876424e-001,2.206213e+000,,,,,,,,,,,,,,64,2,3.000000e+000,1.604462e-002,0.000000e+000,0,,0,
1454905179.223,,-6.025058e+003,7.698906e+001,-5.279422e-003,6.742639e-005,3,9.730067e-001,1.277155e+000,,,,,,,,,,,,,,64,2,3.000000e+000,1.400757e-002,0.000000e+000,0,,0,
1454905238.193,,-4.016779e+003,7.699858e+001,-5.631041e-003,5.709021e-005,3,9.890649e-001,1.013848e+000,,,,,,,,,,,,,,64,2,3.000000e+000,2.204895e-002,0.000000e+000,0,,0,
1454905297.004,,-2.009910e+003,7.699657e+001,-5.996960e-003,4.007145e-005,3,9.898989e-001,6.681960e-001,,,,,,,,,,,,,,64,2,3.000000e+000,1.203918e-002,0.000000e+000,0,,0,
1454905355.705,,-8.748085e-001,7.699658e+001,-1.153239e-002,1.978235e-004,3,9.933988e-001,1.715373e+000,,,,,,,,,,,,,,64,2,3.000000e+000,2.604675e-002,0.000000e+000,0,,0,
1454905421.245,,2.009614e+003,7.698656e+001,-5.169624e-003,5.469344e-005,3,9.862188e-001,1.057977e+000,,,,,,,,,,,,,,64,2,3.000000e+000,2.402496e-002,0.000000e+000,0,,0,
1454905479.166,,4.017744e+003,7.699107e+001,-4.155120e-003,7.284490e-006,3,9.850791e-001,1.753136e-001,,,,,,,,,,,,,,64,2,3.000000e+000,2.003479e-002,0.000000e+000,0,,0,
1454905537.587,,6.025651e+003,7.699657e+001,-3.336708e-003,6.473871e-005,3,9.838670e-001,1.940197e+000,,,,,,,,,,,,,,64,2,3.000000e+000,1.603699e-002,0.000000e+000,0,,0,
1454905661.799,,8.038452e+003,7.698706e+001,-2.339817e-003,9.592721e-005,3,9.771371e-001,4.099775e+000,,,,,,,,,,,,,,64,2,3.000000e+000,1.000977e-002,0.000000e+000,0,,0,
1454905718.481,,1.004577e+004,7.700810e+001,-1.515483e-003,1.754508e-004,3,9.286176e-001,1.157722e+001,,,,,,,,,,,,,,64,2,3.000000e+000,2.406311e-002,0.000000e+000,0,,0,