File: SP-M4-239-3-0104-#4/Pristine/Tc SPM4-239-3-0104-#4-BL.txt
[Header]
TITLE,MPMS DC Measurement
BYAPP,MPMS Measurement,2.1,Summary
FILEOPENTIME, 1454916201.775000 2/8/2016, 1:23:21 AM

INFO, APPNAME, MPMS MultiVu Application, Revision 1.60,  Build 081

INFO, NAME, tb11c
INFO, WEIGHT, 0.100
INFO, AREA, 1.000
INFO, LENGTH, 1.000
INFO, SHAPE, 1
INFO, COMMENT, 650C in 0.1% O2 in AR, single xtal, H//ab, lN2 quench
INFO, SEQUENCE FILE: Sequence_MT_5_27_77_45.seq


INFO, BACKGROUND DATA FILE:, None


STARTUPAXIS,X,4,LINEAR,AUTO,0.000000,0.000000
STARTUPAXIS,Y1,5,LINEAR,AUTO,0.000000,0.000000


STARTUPGROUP,Longitudinal
FIELDGROUP,Longitudinal,1,2,3,4,5,6,7,8,9,15,16,17,18,27,28
FIELDGROUP,Transverse,1,2,3,4,10,11,12,13,14,19,20,21,22,27,28

PLOT_APPEARANCE,ALL,HORZ_GRID_ON,VERT_GRID_ON,MARKERS_AND_LINES

[Data]
Time,Comment,Field (Oe),Temperature (K),Long Moment (emu),Long Scan Std Dev,Long Algorithm,Long Reg Fit,Long Percent Error (%),Trans Moment (emu),Trans Scan Std Dev,Trans Algorithm,Trans Reg Fit,Trans Percent Error (%),Long Moment [w/o ABS] (emu),Long Scan Std Dev [w/o ABS],Long Reg Fit [w/o ABS],Long Percent Error [w/o ABS] (%),Trans Moment [w/o ABS] (emu),Trans Scan Std Dev [w/o ABS],Trans Reg Fit [w/o ABS],Trans Percent Error [w/o ABS] (%),Points per Scan,Scans per Measurement,Scan Length (cm),Delta Temp (K),Rot Position (deg),Error,EC Comp. Running,Using ABS,
1454916201.775,,2.000000e+001,7.498363e+001,-2.106661e-003,3.901911e-008,3,9.962389e-001,1.852178e-003,,,,,,,,,,,,,,64,2,3.000000e+000,2.862549e-002,0.000000e+000,0,,0,
1454916291.557,,2.000000e+001,7.538567e+001,-2.105308e-003,3.669739e-007,3,9.961060e-001,1.743089e-002,,,,,,,,,,,,,,64,2,3.000000e+000,3.836365e-001,0.000000e+000,0,,0,
1454916333.958,,2.000000e+001,7.580126e+001,-2.104105e-003,1.069970e-006,3,9.962517e-001,5.085155e-002,,,,,,,,,,,,,,64,2,3.000000e+000,4.244537e-001,0.000000e+000,0,,0,
1454916377.129,,2.000000e+001,7.621998e+001,-2.100342e-003,1.341949e-006,3,9.962308e-001,6.389192e-002,,,,,,,,,,,,,,64,2,3.000000e+000,3.657684e-001,0.000000e+000,0,,0,
1454916419.280,,2.000000e+001,7.657900e+001,-2.096264e-003,1.469048e-006,3,9.962318e-001,7.007936e-002,,,,,,,,,,,,,,64,2,3.000000e+000,3.472137e-001,0.000000e+000,0,,0,
1454916461.640,,2.000000e+001,7.692865e+001,-2.092130e-003,1.426407e-006,3,9.962324e-001,6.817968e-002,,,,,,,,,,,,,,64,2,3.000000e+000,3.221436e-001,0.000000e+000,0,,0,
1454916504.641,,2.000000e+001,7.726057e+001,-2.087845e-003,1.346723e-006,3,9.962242e-001,6.450303e-002,,,,,,,,,,,,,,64,2,3.000000e+000,3.004990e-001,0.000000e+000,0,,0,
1454916547.662,,2.000000e+001,7.759621e+001,-2.083436e-003,1.464438e-006,3,9.961991e-001,7.028957e-002,,,,,,,,,,,,,,64,2,3.000000e+000,3.110657e-001,0.000000e+000,0,,0,
1454916591.373,,2.000000e+001,7.793251e+001,-2.078713e-003,1.622489e-006,3,9.962032e-001,7.805257e-002,,,,,,,,,,,,,,64,2,3.000000e+000,3.257904e-001,0.000000e+000,0,,0,
1454916633.764,,2.000000e+001,7.826394e+001,-2.073907e-003,1.817089e-006,3,9.961973e-001,8.761671e-002,,,,,,,,,,,,,,64,2,3.000000e+000,2.907104e-001,0.000000e+000,0,,0,
1454916676.025,,2.000000e+001,7.856640e+001,-2.069043e-003,1.786961e-006,3,9.961836e-001,8.636653e-002,,,,,,,,,,,,,,64,2,3.000000e+000,3.098602e-001,0.000000e+000,0,,0,
1454916718.866,,2.000000e+001,7.892084e+001,-2.063424e-003,2.108660e-006,3,9.961596e-001,1.021923e-001,,,,,,,,,,,,,,64,2,3.000000e+000,3.585205e-001,0.000000e+000,0,,0,
1454916761.906,,2.000000e+001,7.928021e+001,-2.056937e-003,2.350181e-006,3,9.961538e-001,1.142563e-001,,,,,,,,,,,,,,64,2,3.000000e+000,3.507996e-001,0.000000e+000,0,,0,
1454916804.497,,2.000000e+001,7.963508e+001,-2.049987e-003,2.611623e-006,3,9.961174e-001,1.273970e-001,,,,,,,,,,,,,,64,2,3.000000e+000,3.408890e-001,0.000000e+000,0,,0,
1454916847.678,,2.000000e+001,7.996973e+001,-2.042408e-003,2.872077e-006,3,9.960963e-001,1.406221e-001,,,,,,,,,,,,,,64,2,3.000000e+000,3.326797e-001,0.000000e+000,0,,0,
1454916890.729,,2.000000e+001,8.032802e+001,-2.034273e-003,3.087915e-006,3,9.960754e-001,1.517945e-001,,,,,,,,,,,,,,64,2,3.000000e+000,3.396835e-001,0.000000e+000,0,,0,
1454916933.870,,2.000000e+001,8.067015e+001,-2.025021e-003,3.323509e-006,3,9.960529e-001,1.641222e-001,,,,,,,,,,,,,,64,2,3.000000e+000,3.662567e-001,0.000000e+000,0,,0,
1454916976.971,,2.000000e+001,8.102197e+001,-2.015175e-003,3.608001e-006,3,9.960341e-001,1.790416e-001,,,,,,,,,,,,,,64,2,3.000000e+000,3.164139e-001,0.000000e+000,0,,0,
1454917019.512,,2.000000e+001,8.135672e+001,-2.004258e-003,4.134013e-006,3,9.960005e-001,2.062615e-001,,,,,,,,,,,,,,64,2,3.000000e+000,3.542175e-001,0.000000e+000,0,,0,
1454917062.372,,2.000000e+001,8.170505e+001,-1.992058e-003,4.377510e-006,3,9.959767e-001,2.197481e-001,,,,,,,,,,,,,,64,2,3.000000e+000,3.301468e-001,0.000000e+000,0,,0,
1454917105.763,,2.000000e+001,8.205782e+001,-1.977562e-003,5.378662e-006,3,9.959260e-001,2.719845e-001,,,,,,,,,,,,,,64,2,3.000000e+000,3.575211e-001,0.000000e+000,0,,0,
1454917149.244,,2.000000e+001,8.241330e+001,-1.961470e-003,5.884589e-006,3,9.958788e-001,3.000092e-001,,,,,,,,,,,,,,64,2,3.000000e+000,3.353653e-001,0.000000e+000,0,,0,
1454917192.165,,2.000000e+001,8.274819e+001,-1.943490e-003,6.550789e-006,3,9.958143e-001,3.370632e-001,,,,,,,,,,,,,,64,2,3.000000e+000,3.446960e-001,0.000000e+000,0,,0,
1454917235.035,,2.000000e+001,8.308836e+001,-1.923330e-003,7.841372e-006,3,9.957679e-001,4.076977e-001,,,,,,,,,,,,,,64,2,3.000000e+000,3.081284e-001,0.000000e+000,0,,0,
1454917277.925,,2.000000e+001,8.343461e+001,-1.898985e-003,8.198550e-006,3,9.957082e-001,4.317333e-001,,,,,,,,,,,,,,64,2,3.000000e+000,3.267136e-001,0.000000e+000,0,,0,
1454917320.895,,2.000000e+001,8.376129e+001,-1.871946e-003,1.019139e-005,3,9.956495e-001,5.444275e-001,,,,,,,,,,,,,,64,2,3.000000e+000,3.499756e-001,0.000000e+000,0,,0,
1454917364.005,,2.000000e+001,8.411317e+001,-1.839841e-003,1.288121e-005,3,9.955624e-001,7.001265e-001,,,,,,,,,,,,,,64,2,3.000000e+000,3.503113e-001,0.000000e+000,0,,0,
1454917407.305,,2.000000e+001,8.445531e+001,-1.799670e-003,1.596921e-005,3,9.954519e-001,8.873411e-001,,,,,,,,,,,,,,64,2,3.000000e+000,3.433838e-001,0.000000e+000,0,,0,
1454917449.375,,2.000000e+001,8.482385e+001,-1.750349e-003,1.781314e-005,3,9.953066e-001,1.017691e+000,,,,,,,,,,,,,,64,2,3.000000e+000,3.700180e-001,0.000000e+000,0,,0,
1454917492.995,,2.000000e+001,8.518324e+001,-1.688795e-003,2.216348e-005,3,9.951382e-001,1.312384e+000,,,,,,,,,,,,,,64,2,3.000000e+000,3.391190e-001,0.000000e+000,0,,0,
1454917535.986,,2.000000e+001,8.553631e+001,-1.618142e-003,2.662331e-005,3,9.949189e-001,1.645301e+000,,,,,,,,,,,,,,64,2,3.000000e+000,3.199081e-001,0.000000e+000,0,,0,
1454917580.067,,2.000000e+001,8.588901e+001,-1.527702e-003,3.630342e-005,3,9.946588e-001,2.376342e+000,,,,,,,,,,,,,,64,2,3.000000e+000,3.320999e-001,0.000000e+000,0,,0,
1454917622.678,,2.000000e+001,8.625047e+001,-1.418323e-003,4.216611e-005,3,9.942266e-001,2.972955e+000,,,,,,,,,,,,,,64,2,3.000000e+000,3.197784e-001,0.000000e+000,0,,0,
1454917665.658,,2.000000e+001,8.658189e+001,-1.285465e-003,5.082268e-005,3,9.937037e-001,3.953641e+000,,,,,,,,,,,,,,64,2,3.000000e+000,3.319778e-001,0.000000e+000,0,,0,
1454917708.249,,2.000000e+001,8.692246e+001,-1.127124e-003,5.872604e-005,3,9.929413e-001,5.210256e+000,,,,,,,,,,,,,,64,2,3.000000e+000,3.243713e-001,0.000000e+000,0,,0,
1454917751.210,,2.000000e+001,8.728119e+001,-9.407645e-004,6.910758e-005,3,9.918880e-001,7.345895e+000,,,,,,,,,,,,,,64,2,3.000000e+000,3.192520e-001,0.000000e+000,0,,0,
1454917835.772,,2.000000e+001,8.797678e+001,-5.141301e-004,7.573754e-005,3,9.851280e-001,1.473120e+001,,,,,,,,,,,,,,64,2,3.000000e+000,3.416672e-001,0.000000e+000,0,,0,
1454917922.254,,2.000000e+001,8.867538e+001,-1.593699e-004,4.942104e-005,3,9.439142e-001,3.101027e+001,,,,,,,,,,,,,,64,2,3.000000e+000,3.180695e-001,0.000000e+000,0,,0,
1454917985.615,,2.000000e+001,8.919141e+001,-6.262604e-006,2.452403e-005,3,4.168772e-001,3.915948e+002,,,,,,,,,,,,,,64,2,3.000000e+000,3.161392e-001,0.000000e+000,0,,0,
1454918029.546,,2.000000e+001,8.954807e+001,1.308978e-005,2.019146e-006,3,7.803723e-001,1.542536e+001,,,,,,,,,,,,,,64,2,3.000000e+000,3.184891e-001,0.000000e+000,0,,0,
1454918072.207,,2.000000e+001,8.990201e+001,9.790567e-006,2.717660e-007,3,9.596313e-001,2.775795e+000,,,,,,,,,,,,,,64,2,3.000000e+000,3.419418e-001,0.000000e+000,0,,0,
1454918114.767,,2.000000e+001,9.024506e+001,9.494103e-006,1.520054e-008,3,9.657376e-001,1.601051e-001,,,,,,,,,,,,,,64,2,3.000000e+000,3.121872e-001,0.000000e+000,0,,0,
1454918158.358,,2.000000e+001,9.060263e+001,9.471880e-006,5.739112e-009,3,9.648271e-001,6.059106e-002,,,,,,,,,,,,,,64,2,3.000000e+000,3.547897e-001,0.000000e+000,0,,0,
1454918200.379,,2.000000e+001,9.092682e+001,9.493168e-006,2.758941e-009,3,9.655383e-001,2.906239e-002,,,,,,,,,,,,,,64,2,3.000000e+000,3.353882e-001,0.000000e+000,0,,0,
1454918328.969,,2.000000e+001,9.198932e+001,9.488056e-006,2.194291e-009,3,9.654756e-001,2.312688e-002,,,,,,,,,,,,,,64,2,3.000000e+000,3.452301e-001,0.000000e+000,0,,0,
1454918371.639,,2.000000e+001,9.232247e+001,9.488618e-006,8.306407e-009,3,9.656267e-001,8.754075e-002,,,,,,,,,,,,,,64,2,3.000000e+000,3.196640e-001,0.000000e+000,0,,0,
1454918413.689,,2.000000e+001,9.264803e+001,9.492396e-006,2.630963e-009,3,9.656067e-001,2.771653e-002,,,,,,,,,,,,,,64,2,3.000000e+000,3.160400e-001,0.000000e+000,0,,0,
1454918456.689,,2.000000e+001,9.297144e+001,9.487762e-006,9.815142e-009,3,9.648226e-001,1.034506e-001,,,,,,,,,,,,,,64,2,3.000000e+000,3.405991e-001,0.000000e+000,0,,0,
1454918499.929,,2.000000e+001,9.331314e+001,9.496285e-006,3.974419e-009,3,9.651450e-001,4.185236e-002,,,,,,,,,,,,,,64,2,3.000000e+000,3.314590e-001,0.000000e+000,0,,0,
1454918542.960,,2.000000e+001,9.364998e+001,9.501235e-006,9.081354e-009,3,9.650854e-001,9.558078e-002,,,,,,,,,,,,,,64,2,3.000000e+000,3.194199e-001,0.000000e+000,0,,0,
1454918585.141,,2.000000e+001,9.397540e+001,9.496976e-006,4.379578e-009,3,9.648139e-001,4.611550e-002,,,,,,,,,,,,,,64,2,3.000000e+000,3.358231e-001,0.000000e+000,0,,0,
1454918627.862,,2.000000e+001,9.433026e+001,9.499112e-006,1.938333e-009,3,9.647392e-001,2.040541e-002,,,,,,,,,,,,,,64,2,3.000000e+000,3.264389e-001,0.000000e+000,0,,0,
1454918670.423,,2.000000e+001,9.466721e+001,9.499339e-006,2.939655e-009,3,9.651306e-001,3.094589e-002,,,,,,,,,,,,,,64,2,3.000000e+000,3.402328e-001,0.000000e+000,0,,0,
1454918807.995,,2.000000e+001,9.496820e+001,9.611242e-006,1.811544e-007,3,9.652656e-001,1.884818e+000,,,,,,,,,,,,,,64,2,3.000000e+000,1.753769e-001,0.000000e+000,0,,0,
1454918914.137,,2.000000e+001,9.497035e+001,9.537202e-006,1.013605e-008,3,9.648454e-001,1.062791e-001,,,,,,,,,,,,,,64,2,3.000000e+000,1.170349e-002,0.000000e+000,0,,0,
1454918999.129,,2.000000e+001,9.497839e+001,9.537859e-006,5.724964e-009,3,9.647558e-001,6.002358e-002,,,,,,,,,,,,,,64,2,3.000000e+000,2.341461e-002,0.000000e+000,0,,0,
1454919040.690,,2.000000e+001,9.497546e+001,9.539019e-006,1.596134e-008,3,9.645038e-001,1.673269e-001,,,,,,,,,,,,,,64,2,3.000000e+000,2.632904e-002,0.000000e+000,0,,0,
1454919083.471,,2.000000e+001,9.498131e+001,9.521191e-006,7.501233e-009,3,9.639378e-001,7.878461e-002,,,,,,,,,,,,,,64,2,3.000000e+000,2.341461e-002,0.000000e+000,0,,0,
1454919126.192,,2.000000e+001,9.499960e+001,9.525886e-006,3.668299e-009,3,9.655449e-001,3.850874e-002,,,,,,,,,,,,,,64,2,3.000000e+000,3.512573e-002,0.000000e+000,0,,0,
1454919168.783,,2.000000e+001,9.499741e+001,9.524838e-006,2.316032e-008,3,9.651599e-001,2.431571e-001,,,,,,,,,,,,,,64,2,3.000000e+000,2.925873e-002,0.000000e+000,0,,0,
1454919210.993,,2.000000e+001,9.500327e+001,9.513482e-006,4.055965e-008,3,9.653252e-001,4.263387e-001,,,,,,,,,,,,,,64,2,3.000000e+000,2.925873e-002,0.000000e+000,0,,0,
1454919252.854,,2.000000e+001,9.500107e+001,9.560426e-006,1.509572e-008,3,9.650835e-001,1.578980e-001,,,,,,,,,,,,,,64,2,3.000000e+000,4.389191e-002,0.000000e+000,0,,0,
1454919295.915,,2.000000e+001,9.499301e+001,9.528019e-006,2.974383e-009,3,9.644390e-001,3.121722e-002,,,,,,,,,,,,,,64,2,3.000000e+000,1.757050e-002,0.000000e+000,0,,0,
1454919337.886,,2.000000e+001,9.499448e+001,9.531325e-006,2.998178e-009,3,9.643750e-001,3.145605e-002,,,,,,,,,,,,,,64,2,3.000000e+000,1.757050e-002,0.000000e+000,0,,0,
1454919380.127,,2.000000e+001,9.500180e+001,9.532761e-006,3.313302e-009,3,9.655930e-001,3.475700e-002,,,,,,,,,,,,,,64,2,3.000000e+000,2.635956e-002,0.000000e+000,0,,0,
1454919422.648,,2.000000e+001,9.498863e+001,9.498410e-006,2.838237e-008,3,9.647033e-001,2.988118e-001,,,,,,,,,,,,,,64,2,3.000000e+000,4.093933e-002,0.000000e+000,0,,0,
1454919464.668,,2.000000e+001,9.498424e+001,9.560577e-006,2.939912e-008,3,9.652411e-001,3.075036e-001,,,,,,,,,,,,,,64,2,3.000000e+000,2.925110e-002,0.000000e+000,0,,0,
1454919507.409,,2.000000e+001,9.499155e+001,9.540076e-006,3.567330e-009,3,9.648416e-001,3.739310e-002,,,,,,,,,,,,,,64,2,3.000000e+000,3.218079e-002,0.000000e+000,0,,0,
1454919549.510,,2.000000e+001,9.499741e+001,9.542759e-006,4.893423e-009,3,9.646111e-001,5.127892e-002,,,,,,,,,,,,,,64,2,3.000000e+000,8.766174e-003,0.000000e+000,0,,0,
1454919591.851,,2.000000e+001,9.499229e+001,9.539997e-006,1.545393e-009,3,9.650112e-001,1.619909e-002,,,,,,,,,,,,,,64,2,3.000000e+000,8.773804e-003,0.000000e+000,0,,0,
1454919635.122,,2.000000e+001,9.499814e+001,9.542306e-006,3.284362e-009,3,9.645563e-001,3.441896e-002,,,,,,,,,,,,,,64,2,3.000000e+000,3.220367e-002,0.000000e+000,0,,0,
1454919677.453,,2.000000e+001,9.500107e+001,9.546054e-006,1.351560e-008,3,9.646292e-001,1.415831e-001,,,,,,,,,,,,,,64,2,3.000000e+000,2.634430e-002,0.000000e+000,0,,0,
1454919720.294,,2.000000e+001,9.498935e+001,9.543629e-006,5.596342e-009,3,9.647937e-001,5.863956e-002,,,,,,,,,,,,,,64,2,3.000000e+000,2.340698e-002,0.000000e+000,0,,0,
1454919762.434,,2.000000e+001,9.498935e+001,9.540374e-006,9.751475e-009,3,9.648539e-001,1.022127e-001,,,,,,,,,,,,,,64,2,3.000000e+000,1.170349e-002,0.000000e+000,0,,0,
1454919805.795,,2.000000e+001,9.499448e+001,9.540407e-006,2.076602e-009,3,9.650513e-001,2.176639e-002,,,,,,,,,,,,,,64,2,3.000000e+000,3.510284e-002,0.000000e+000,0,,0,
1454919847.806,,2.000000e+001,9.498570e+001,9.548324e-006,4.759013e-011,3,9.653444e-001,4.984135e-004,,,,,,,,,,,,,,64,2,3.000000e+000,2.925110e-002,0.000000e+000,0,,0,
1454919890.307,,2.000000e+001,9.499448e+001,9.547426e-006,7.132092e-010,3,9.650623e-001,7.470172e-003,,,,,,,,,,,,,,64,2,3.000000e+000,1.753998e-002,0.000000e+000,0,,0,
1454919932.188,,2.000000e+001,9.498790e+001,9.552326e-006,1.606488e-009,3,9.652467e-001,1.681777e-002,,,,,,,,,,,,,,64,2,3.000000e+000,3.509521e-002,0.000000e+000,0,,0,
1454919974.939,,2.000000e+001,9.497693e+001,9.549396e-006,8.656259e-010,3,9.645161e-001,9.064719e-003,,,,,,,,,,,,,,64,2,3.000000e+000,2.340698e-002,0.000000e+000,0,,0,
1454920017.159,,2.000000e+001,9.498716e+001,9.547792e-006,7.350103e-009,3,9.651101e-001,7.698223e-002,,,,,,,,,,,,,,64,2,3.000000e+000,2.927399e-002,0.000000e+000,0,,0,
1454920059.510,,2.000000e+001,9.500546e+001,9.551708e-006,1.096052e-008,3,9.655739e-001,1.147493e-001,,,,,,,,,,,,,,64,2,3.000000e+000,2.340698e-002,0.000000e+000,0,,0,
1454920102.791,,2.000000e+001,9.500180e+001,9.549478e-006,6.545572e-009,3,9.646738e-001,6.854377e-002,,,,,,,,,,,,,,64,2,3.000000e+000,3.804016e-002,0.000000e+000,0,,0,
1454920145.662,,2.000000e+001,9.498279e+001,9.550135e-006,7.261354e-009,3,9.647109e-001,7.603405e-002,,,,,,,,,,,,,,64,2,3.000000e+000,3.218079e-002,0.000000e+000,0,,0,
1454920187.983,,2.000000e+001,9.499667e+001,9.551582e-006,1.603273e-009,3,9.644642e-001,1.678542e-002,,,,,,,,,,,,,,64,2,3.000000e+000,1.169586e-002,0.000000e+000,0,,0,
1454920230.984,,2.000000e+001,9.500400e+001,9.550358e-006,1.460503e-009,3,9.652895e-001,1.529265e-002,,,,,,,,,,,,,,64,2,3.000000e+000,2.048492e-002,0.000000e+000,0,,0,
1454920273.315,,2.000000e+001,9.498788e+001,9.549944e-006,3.484369e-009,3,9.649491e-001,3.648575e-002,,,,,,,,,,,,,,64,2,3.000000e+000,2.633667e-002,0.000000e+000,0,,0,
1454920315.425,,2.000000e+001,9.499009e+001,9.549572e-006,4.788596e-009,3,9.650391e-001,5.014461e-002,,,,,,,,,,,,,,64,2,3.000000e+000,2.339172e-002,0.000000e+000,0,,0,
1454920357.296,,2.000000e+001,9.498496e+001,9.555073e-006,9.653082e-010,3,9.647177e-001,1.010257e-002,,,,,,,,,,,,,,64,2,3.000000e+000,2.633667e-002,0.000000e+000,0,,0,
1454920399.737,,2.000000e+001,9.499375e+001,9.549843e-006,1.422559e-009,3,9.649950e-001,1.489615e-002,,,,,,,,,,,,,,64,2,3.000000e+000,3.804016e-002,0.000000e+000,0,,0,
1454920442.408,,2.000000e+001,9.499009e+001,9.549378e-006,2.919719e-009,3,9.645350e-001,3.057496e-002,,,,,,,,,,,,,,64,2,3.000000e+000,2.633667e-002,0.000000e+000,0,,0,
1454920484.819,,2.000000e+001,9.497912e+001,9.561294e-006,6.027869e-009,3,9.647535e-001,6.304449e-002,,,,,,,,,,,,,,64,2,3.000000e+000,2.924347e-002,0.000000e+000,0,,0,
1454920569.431,,2.000000e+001,9.499668e+001,9.548949e-006,1.531245e-009,3,9.641237e-001,1.603574e-002,,,,,,,,,,,,,,64,2,3.000000e+000,4.096985e-002,0.000000e+000,0,,0,
1454920611.331,,2.000000e+001,9.499083e+001,9.551396e-006,1.196056e-008,3,9.650402e-001,1.252231e-001,,,,,,,,,,,,,,64,2,3.000000e+000,5.836487e-003,0.000000e+000,0,,0,
1454920697.433,,2.000000e+001,9.499595e+001,9.562735e-006,1.592983e-009,3,9.653292e-001,1.665824e-002,,,,,,,,,,,,,,64,2,3.000000e+000,1.169586e-002,0.000000e+000,0,,0,
1454920739.184,,2.000000e+001,9.499374e+001,9.559978e-006,4.553218e-009,3,9.653828e-001,4.762791e-002,,,,,,,,,,,,,,64,2,3.000000e+000,2.048492e-002,0.000000e+000,0,,0,
1454920781.555,,2.000000e+001,9.499667e+001,9.558883e-006,6.088964e-009,3,9.643736e-001,6.369954e-002,,,,,,,,,,,,,,64,2,3.000000e+000,2.048492e-002,0.000000e+000,0,,0,
1454920823.446,,2.000000e+001,9.499081e+001,9.557156e-006,4.322342e-009,3,9.646277e-001,4.522623e-002,,,,,,,,,,,,,,64,2,3.000000e+000,2.048492e-002,0.000000e+000,0,,0,
1454920865.326,,2.000000e+001,9.498495e+001,9.557287e-006,7.907679e-009,3,9.650135e-001,8.273979e-002,,,,,,,,,,,,,,64,2,3.000000e+000,2.914429e-003,0.000000e+000,0,,0,
1454920907.907,,2.000000e+001,9.501131e+001,9.549998e-006,1.740577e-008,3,9.650379e-001,1.822594e-001,,,,,,,,,,,,,,64,2,3.000000e+000,2.341461e-002,0.000000e+000,0,,0,
1454920950.008,,2.000000e+001,9.499228e+001,9.558384e-006,7.762339e-010,3,9.650193e-001,8.120974e-003,,,,,,,,,,,,,,64,2,3.000000e+000,1.757050e-002,0.000000e+000,0,,0,
1454920993.419,,2.000000e+001,9.499374e+001,9.563106e-006,3.211048e-009,3,9.655223e-001,3.357746e-002,,,,,,,,,,,,,,64,2,3.000000e+000,2.048492e-002,0.000000e+000,0,,0,